Workbook

Sheet 工作表1
A1: =[1]攻守數據!AG2 -> 寶可夢 | B1: =[1]攻守數據!AH2 -> 屬性一 | C1: =[1]攻守數據!AI2 -> 屬性二 | D1: =[1]攻守數據!AJ2 -> 基礎防禦 | E1: =[1]攻守數據!AK2 -> 開三盾 | G1: 攻/守 | H1: 一般 | I1: 火 | J1: 格鬥 | K1: 水 | L1: 飛行 | M1: 草 | N1: 毒 | O1: 電 | P1: 地面 | Q1: 超能力 | R1: 岩石 | S1: 冰 | T1: 蟲 | U1: 龍 | V1: 幽靈 | W1: 惡 | X1: 鋼 | Y1: 妖精 | Z1: 無
A2: =[1]攻守數據!AG3 -> 幸福蛋 | B2: =[1]攻守數據!AH3 -> 一般 | C2: =[1]攻守數據!AI3 -> 無 | D2: =IF([1]攻守數據!AJ3 = "", "", [1]攻守數據!AJ3) -> 61.686 | E2: =IF([1]攻守數據!AK3 = "", "", [1]攻守數據!AK3) -> 88.506 | G2: 一般 | H2: 1 | I2: 1 | J2: 1 | K2: 1 | L2: 1 | M2: 1 | N2: 1 | O2: 1 | P2: 1 | Q2: 1 | R2: 0.625 | S2: 1 | T2: 1 | U2: 1 | V2: 0.391 | W2: 1 | X2: 0.625 | Y2: 1 | Z2: 1
A3: =[1]攻守數據!AG4 -> 藏瑪然特 | B3: =[1]攻守數據!AH4 -> 鋼 | C3: =[1]攻守數據!AI4 -> 格鬥 | D3: =IF([1]攻守數據!AJ4 = "", "", [1]攻守數據!AJ4) -> 58.25 | E3: =IF([1]攻守數據!AK4 = "", "", [1]攻守數據!AK4) -> 103.73 | G3: 火 | H3: 1 | I3: 0.625 | J3: 1 | K3: 0.625 | L3: 1 | M3: 1.6 | N3: 1 | O3: 1 | P3: 1 | Q3: 1 | R3: 0.625 | S3: 1.6 | T3: 1.6 | U3: 0.625 | V3: 1 | W3: 1 | X3: 1.6 | Y3: 1 | Z3: 1
A4: =[1]攻守數據!AG5 -> 卡比獸 | B4: =[1]攻守數據!AH5 -> 一般 | C4: =[1]攻守數據!AI5 -> 無 | D4: =IF([1]攻守數據!AJ5 = "", "", [1]攻守數據!AJ5) -> 39.44 | E4: =IF([1]攻守數據!AK5 = "", "", [1]攻守數據!AK5) -> 65.54 | G4: 格鬥 | H4: 1.6 | I4: 1 | J4: 1 | K4: 1 | L4: 0.625 | M4: 1 | N4: 0.625 | O4: 1 | P4: 1 | Q4: 0.625 | R4: 1.6 | S4: 1.6 | T4: 0.625 | U4: 1 | V4: 0.391 | W4: 1.6 | X4: 1.6 | Y4: 0.625 | Z4: 1
A5: =[1]攻守數據!AG6 -> 水君 | B5: =[1]攻守數據!AH6 -> 水 | C5: =[1]攻守數據!AI6 -> 無 | D5: =IF([1]攻守數據!AJ6 = "", "", [1]攻守數據!AJ6) -> 37.422 | E5: =IF([1]攻守數據!AK6 = "", "", [1]攻守數據!AK6) -> 73.062 | G5: 水 | H5: 1 | I5: 1.6 | J5: 1 | K5: 0.625 | L5: 1 | M5: 0.625 | N5: 1 | O5: 1 | P5: 1.6 | Q5: 1 | R5: 1.6 | S5: 1 | T5: 1 | U5: 0.625 | V5: 1 | W5: 1 | X5: 1 | Y5: 1 | Z5: 1
A6: =[1]攻守數據!AG7 -> 無極汰那 | B6: =[1]攻守數據!AH7 -> 龍 | C6: =[1]攻守數據!AI7 -> 毒 | D6: =IF([1]攻守數據!AJ7 = "", "", [1]攻守數據!AJ7) -> 38.701 | E6: =IF([1]攻守數據!AK7 = "", "", [1]攻守數據!AK7) -> 69.121 | G6: 飛行 | H6: 1 | I6: 1 | J6: 1.6 | K6: 1 | L6: 1 | M6: 1.6 | N6: 1 | O6: 0.625 | P6: 1 | Q6: 1 | R6: 0.625 | S6: 1 | T6: 1.6 | U6: 1 | V6: 1 | W6: 1 | X6: 0.625 | Y6: 1 | Z6: 1
A7: =[1]攻守數據!AG8 -> 急凍鳥 | B7: =[1]攻守數據!AH8 -> 冰 | C7: =[1]攻守數據!AI8 -> 飛行 | D7: =IF([1]攻守數據!AJ8 = "", "", [1]攻守數據!AJ8) -> 34.65 | E7: =IF([1]攻守數據!AK8 = "", "", [1]攻守數據!AK8) -> 70.29 | G7: 草 | H7: 1 | I7: 0.625 | J7: 1 | K7: 1.6 | L7: 0.625 | M7: 0.625 | N7: 0.625 | O7: 1 | P7: 1.6 | Q7: 1 | R7: 1.6 | S7: 1 | T7: 0.625 | U7: 0.625 | V7: 1 | W7: 1 | X7: 0.625 | Y7: 1 | Z7: 1
A8: =[1]攻守數據!AG9 -> 拉普拉斯 | B8: =[1]攻守數據!AH9 -> 水 | C8: =[1]攻守數據!AI9 -> 冰 | D8: =IF([1]攻守數據!AJ9 = "", "", [1]攻守數據!AJ9) -> 33.81 | E8: =IF([1]攻守數據!AK9 = "", "", [1]攻守數據!AK9) -> 60.27 | G8: 毒 | H8: 1 | I8: 1 | J8: 1 | K8: 1 | L8: 1 | M8: 1.6 | N8: 0.625 | O8: 1 | P8: 0.625 | Q8: 1 | R8: 0.625 | S8: 1 | T8: 1 | U8: 1 | V8: 0.625 | W8: 1 | X8: 0.391 | Y8: 1.6 | Z8: 1
A9: =[1]攻守數據!AG10 -> 拉帝亞斯 | B9: =[1]攻守數據!AH10 -> 龍 | C9: =[1]攻守數據!AI10 -> 超能力 | D9: =IF([1]攻守數據!AJ10 = "", "", [1]攻守數據!AJ10) -> 31.916 | E9: =IF([1]攻守數據!AK10 = "", "", [1]攻守數據!AK10) -> 68.276 | G9: 電 | H9: 1 | I9: 1 | J9: 1 | K9: 1.6 | L9: 1.6 | M9: 0.625 | N9: 1 | O9: 0.625 | P9: 0.391 | Q9: 1 | R9: 1 | S9: 1 | T9: 1 | U9: 0.625 | V9: 1 | W9: 1 | X9: 1 | Y9: 1 | Z9: 1
A10: =[1]攻守數據!AG11 -> 蒼響 | B10: =[1]攻守數據!AH11 -> 鋼 | C10: =[1]攻守數據!AI11 -> 妖精 | D10: =IF([1]攻守數據!AJ11 = "", "", [1]攻守數據!AJ11) -> 36.849 | E10: =IF([1]攻守數據!AK11 = "", "", [1]攻守數據!AK11) -> 75.189 | G10: 地面 | H10: 1 | I10: 1.6 | J10: 1 | K10: 1 | L10: 0.391 | M10: 0.625 | N10: 1.6 | O10: 1.6 | P10: 1 | Q10: 1 | R10: 1.6 | S10: 1 | T10: 0.625 | U10: 1 | V10: 1 | W10: 1 | X10: 1.6 | Y10: 1 | Z10: 1
A11: =[1]攻守數據!AG12 -> 拉帝歐斯 | B11: =[1]攻守數據!AH12 -> 龍 | C11: =[1]攻守數據!AI12 -> 超能力 | D11: =IF([1]攻守數據!AJ12 = "", "", [1]攻守數據!AJ12) -> 28.64 | E11: =IF([1]攻守數據!AK12 = "", "", [1]攻守數據!AK12) -> 60.86 | G11: 超能力 | H11: 1 | I11: 1 | J11: 1.6 | K11: 1 | L11: 1 | M11: 1 | N11: 1.6 | O11: 1 | P11: 1 | Q11: 0.625 | R11: 1 | S11: 1 | T11: 1 | U11: 1 | V11: 1 | W11: 0.391 | X11: 0.625 | Y11: 1 | Z11: 1
A12: =[1]攻守數據!AG13 -> 巨金怪 | B12: =[1]攻守數據!AH13 -> 鋼 | C12: =[1]攻守數據!AI13 -> 超能力 | D12: =IF([1]攻守數據!AJ13 = "", "", [1]攻守數據!AJ13) -> 30.429 | E12: =IF([1]攻守數據!AK13 = "", "", [1]攻守數據!AK13) -> 64.449 | G12: 岩石 | H12: 1 | I12: 1.6 | J12: 0.625 | K12: 1 | L12: 1.6 | M12: 1 | N12: 1 | O12: 1 | P12: 0.625 | Q12: 1 | R12: 1 | S12: 1.6 | T12: 1.6 | U12: 1 | V12: 1 | W12: 1 | X12: 0.625 | Y12: 1 | Z12: 1
A13: =[1]攻守數據!AG14 -> 炎帝 | B13: =[1]攻守數據!AH14 -> 火 | C13: =[1]攻守數據!AI14 -> 無 | D13: =IF([1]攻守數據!AJ14 = "", "", [1]攻守數據!AJ14) -> 30.015 | E13: =IF([1]攻守數據!AK14 = "", "", [1]攻守數據!AK14) -> 56.115 | G13: 冰 | H13: 1 | I13: 0.625 | J13: 1 | K13: 0.625 | L13: 1.6 | M13: 1.6 | N13: 1 | O13: 1 | P13: 1.6 | Q13: 1 | R13: 1 | S13: 0.625 | T13: 1 | U13: 1.6 | V13: 1 | W13: 1 | X13: 0.625 | Y13: 1 | Z13: 1
... A20: =[1]攻守數據!AG21 -> 水箭龜 | B20: =[1]攻守數據!AH21 -> 水 | C20: =[1]攻守數據!AI21 -> 無 | D20: =IF([1]攻守數據!AJ21 = "", "", [1]攻守數據!AJ21) -> 27.825 | E20: =IF([1]攻守數據!AK21 = "", "", [1]攻守數據!AK21) -> 59.325 | G20: 無 | H20: 1 | I20: 1 | J20: 1 | K20: 1 | L20: 1 | M20: 1 | N20: 1 | O20: 1 | P20: 1 | Q20: 1 | R20: 1 | S20: 1 | T20: 1 | U20: 1 | V20: 1 | W20: 1 | X20: 1 | Y20: 1 | Z20: 1
A21: =[1]攻守數據!AG22 -> 閃電鳥 | B21: =[1]攻守數據!AH22 -> 電 | C21: =[1]攻守數據!AI22 -> 飛行 | D21: =IF([1]攻守數據!AJ22 = "", "", [1]攻守數據!AJ22) -> 27.65 | E21: =IF([1]攻守數據!AK22 = "", "", [1]攻守數據!AK22) -> 56.09
A22: =[1]攻守數據!AG23 -> 轟擂金剛猩 | B22: =[1]攻守數據!AH23 -> 草 | C22: =[1]攻守數據!AI23 -> 無 | D22: =IF([1]攻守數據!AJ23 = "", "", [1]攻守數據!AJ23) -> 28.86 | E22: =IF([1]攻守數據!AK23 = "", "", [1]攻守數據!AK23) -> 55.5
A23: =[1]攻守數據!AG24 -> 火焰鳥 | B23: =[1]攻守數據!AH24 -> 火 | C23: =[1]攻守數據!AI24 -> 飛行 | D23: =IF([1]攻守數據!AJ24 = "", "", [1]攻守數據!AJ24) -> 26.95 | E23: =IF([1]攻守數據!AK24 = "", "", [1]攻守數據!AK24) -> 54.67
A24: =[1]攻守數據!AG25 -> 投擲猴 | B24: =[1]攻守數據!AH25 -> 格鬥 | C24: =[1]攻守數據!AI25 -> 無 | D24: =IF([1]攻守數據!AJ25 = "", "", [1]攻守數據!AJ25) -> 26.082 | E24: =IF([1]攻守數據!AK25 = "", "", [1]攻守數據!AK25) -> 50.922
A25: =[1]攻守數據!AG26 -> 妙蛙花 | B25: =[1]攻守數據!AH26 -> 草 | C25: =[1]攻守數據!AI26 -> 毒 | D25: =IF([1]攻守數據!AJ26 = "", "", [1]攻守數據!AJ26) -> 26.082 | E25: =IF([1]攻守數據!AK26 = "", "", [1]攻守數據!AK26) -> 55.062
A26: =[1]攻守數據!AG27 -> 毛毛角羊 | B26: =[1]攻守數據!AH27 -> 一般 | C26: =[1]攻守數據!AI27 -> 無 | D26: =IF([1]攻守數據!AJ27 = "", "", [1]攻守數據!AJ27) -> 24.883 | E26: =IF([1]攻守數據!AK27 = "", "", [1]攻守數據!AK27) -> 54.943
A27: =[1]攻守數據!AG28 -> 多刺菊石獸 | B27: =[1]攻守數據!AH28 -> 岩石 | C27: =[1]攻守數據!AI28 -> 水 | D27: =IF([1]攻守數據!AJ28 = "", "", [1]攻守數據!AJ28) -> 25.456 | E27: =IF([1]攻守數據!AK28 = "", "", [1]攻守數據!AK28) -> 56.416
A28: =[1]攻守數據!AG29 -> 壺壺 | B28: =[1]攻守數據!AH29 -> 岩石 | C28: =[1]攻守數據!AI29 -> 蟲 | D28: =IF([1]攻守數據!AJ29 = "", "", [1]攻守數據!AJ29) -> 33.66 | E28: =IF([1]攻守數據!AK29 = "", "", [1]攻守數據!AK29) -> 104.94
A29: =[1]攻守數據!AG30 -> 怪力 | B29: =[1]攻守數據!AH30 -> 格鬥 | C29: =[1]攻守數據!AI30 -> 無 | D29: =IF([1]攻守數據!AJ30 = "", "", [1]攻守數據!AJ30) -> 25.38 | E29: =IF([1]攻守數據!AK30 = "", "", [1]攻守數據!AK30) -> 50.76
A30: =[1]攻守數據!AG31 -> 噴火龍 | B30: =[1]攻守數據!AH31 -> 火 | C30: =[1]攻守數據!AI31 -> 飛行 | D30: =IF([1]攻守數據!AJ31 = "", "", [1]攻守數據!AJ31) -> 22.62 | E30: =IF([1]攻守數據!AK31 = "", "", [1]攻守數據!AK31) -> 48.72
A31: =[1]攻守數據!AG32 -> 龍頭地鼠 | B31: =[1]攻守數據!AH32 -> 地面 | C31: =[1]攻守數據!AI32 -> 鋼 | D31: =IF([1]攻守數據!AJ32 = "", "", [1]攻守數據!AJ32) -> 24.453 | E31: =IF([1]攻守數據!AK32 = "", "", [1]攻守數據!AK32) -> 45.513
A32: =[1]攻守數據!AG33 -> 灰塵山 | B32: =[1]攻守數據!AH33 -> 毒 | C32: =[1]攻守數據!AI33 -> 無 | D32: =IF([1]攻守數據!AJ33 = "", "", [1]攻守數據!AJ33) -> 22.68 | E32: =IF([1]攻守數據!AK33 = "", "", [1]攻守數據!AK33) -> 47.88
... A65: =[1]攻守數據!AG66 -> 帝牙海獅 | B65: =[1]攻守數據!AH66 -> 水 | C65: =[1]攻守數據!AI66 -> 冰 | D65: =IF([1]攻守數據!AJ66 = "", "", [1]攻守數據!AJ66) -> 30.653 | E65: =IF([1]攻守數據!AK66 = "", "", [1]攻守數據!AK66) -> 57.833
A66: =IF([1]攻守數據!AG67 = "", "", [1]攻守數據!AG67) -> 龐岩怪 | B66: =IF([1]攻守數據!AH67 = "", "", [1]攻守數據!AH67) -> 岩石 | C66: =IF([1]攻守數據!AI67 = "", "", [1]攻守數據!AI67) -> 無 | D66: =IF([1]攻守數據!AJ67 = "", "", [1]攻守數據!AJ67) -> 28.728 | E66: =IF([1]攻守數據!AK67 = "", "", [1]攻守數據!AK67) -> 59.508
A67: =IF([1]攻守數據!AG68 = "", "", [1]攻守數據!AG68) -> 老翁龍 | B67: =IF([1]攻守數據!AH68 = "", "", [1]攻守數據!AH68) -> 龍 | C67: =IF([1]攻守數據!AI68 = "", "", [1]攻守數據!AI68) -> 一般 | D67: =IF([1]攻守數據!AJ68 = "", "", [1]攻守數據!AJ68) -> 22.278 | E67: =IF([1]攻守數據!AK68 = "", "", [1]攻守數據!AK68) -> 47.658
A68: =IF([1]攻守數據!AG69 = "", "", [1]攻守數據!AG69) -> 鳳王 | B68: =IF([1]攻守數據!AH69 = "", "", [1]攻守數據!AH69) -> 飛行 | C68: =IF([1]攻守數據!AI69 = "", "", [1]攻守數據!AI69) -> 火 | D68: =IF([1]攻守數據!AJ69 = "", "", [1]攻守數據!AJ69) -> 37.44 | E68: =IF([1]攻守數據!AK69 = "", "", [1]攻守數據!AK69) -> 74.88
A69: =IF([1]攻守數據!AG70 = "", "", [1]攻守數據!AG70) -> 風速狗 | B69: =IF([1]攻守數據!AH70 = "", "", [1]攻守數據!AH70) -> 火 | C69: =IF([1]攻守數據!AI70 = "", "", [1]攻守數據!AI70) -> 無 | D69: =IF([1]攻守數據!AJ70 = "", "", [1]攻守數據!AJ70) -> 25.025 | E69: =IF([1]攻守數據!AK70 = "", "", [1]攻守數據!AK70) -> 50.765
A70: =IF([1]攻守數據!AG71 = "", "", [1]攻守數據!AG71) -> 固拉多 | B70: =IF([1]攻守數據!AH71 = "", "", [1]攻守數據!AH71) -> 地面 | C70: =IF([1]攻守數據!AI71 = "", "", [1]攻守數據!AI71) -> 無 | D70: =IF([1]攻守數據!AJ71 = "", "", [1]攻守數據!AJ71) -> 33.216 | E70: =IF([1]攻守數據!AK71 = "", "", [1]攻守數據!AK71) -> 67.776
A71: =IF([1]攻守數據!AG72 = "", "", [1]攻守數據!AG72) -> 蓋歐卡 | B71: =IF([1]攻守數據!AH72 = "", "", [1]攻守數據!AH72) -> 水 | C71: =IF([1]攻守數據!AI72 = "", "", [1]攻守數據!AI72) -> 無 | D71: =IF([1]攻守數據!AJ72 = "", "", [1]攻守數據!AJ72) -> 33.216 | E71: =IF([1]攻守數據!AK72 = "", "", [1]攻守數據!AK72) -> 67.776
A72: =IF([1]攻守數據!AG73 = "", "", [1]攻守數據!AG73) -> 烈空坐 | B72: =IF([1]攻守數據!AH73 = "", "", [1]攻守數據!AH73) -> 龍 | C72: =IF([1]攻守數據!AI73 = "", "", [1]攻守數據!AI73) -> 飛行 | D72: =IF([1]攻守數據!AJ73 = "", "", [1]攻守數據!AJ73) -> 26.28 | E72: =IF([1]攻守數據!AK73 = "", "", [1]攻守數據!AK73) -> 52.56
A73: =IF([1]攻守數據!AG74 = "", "", [1]攻守數據!AG74) -> 喵喵 | B73: =IF([1]攻守數據!AH74 = "", "", [1]攻守數據!AH74) -> 一般 | C73: =IF([1]攻守數據!AI74 = "", "", [1]攻守數據!AI74) -> 無 | D73: =IF([1]攻守數據!AJ74 = "", "", [1]攻守數據!AJ74) -> 7.738 | E73: =IF([1]攻守數據!AK74 = "", "", [1]攻守數據!AK74) -> 20.878
A74: =IF([1]攻守數據!AG75 = "", "", [1]攻守數據!AG75) -> 皮卡丘 | B74: =IF([1]攻守數據!AH75 = "", "", [1]攻守數據!AH75) -> 電 | C74: =IF([1]攻守數據!AI75 = "", "", [1]攻守數據!AI75) -> 無 | D74: =IF([1]攻守數據!AJ75 = "", "", [1]攻守數據!AJ75) -> 8.712 | E74: =IF([1]攻守數據!AK75 = "", "", [1]攻守數據!AK75) -> 24.552
A75: =IF([1]攻守數據!AG76 = "", "", [1]攻守數據!AG76) -> 雷丘 | B75: =IF([1]攻守數據!AH76 = "", "", [1]攻守數據!AH76) -> 電 | C75: =IF([1]攻守數據!AI76 = "", "", [1]攻守數據!AI76) -> 無 | D75: =IF([1]攻守數據!AJ76 = "", "", [1]攻守數據!AJ76) -> 17.554 | E75: =IF([1]攻守數據!AK76 = "", "", [1]攻守數據!AK76) -> 41.134
A76: =IF([1]攻守數據!AG77 = "", "", [1]攻守數據!AG77) -> 雷吉艾斯 | B76: =IF([1]攻守數據!AH77 = "", "", [1]攻守數據!AH77) -> 冰 | C76: =IF([1]攻守數據!AI77 = "", "", [1]攻守數據!AI77) -> 無 | D76: =IF([1]攻守數據!AJ77 = "", "", [1]攻守數據!AJ77) -> 41.472 | E76: =IF([1]攻守數據!AK77 = "", "", [1]攻守數據!AK77) -> 87.552
A77: =IF([1]攻守數據!AG78 = "", "", [1]攻守數據!AG78) -> 沙漠蜻蜓 | B77: =IF([1]攻守數據!AH78 = "", "", [1]攻守數據!AH78) -> 地面 | C77: =IF([1]攻守數據!AI78 = "", "", [1]攻守數據!AI78) -> 龍 | D77: =IF([1]攻守數據!AJ78 = "", "", [1]攻守數據!AJ78) -> 23.328 | E77: =IF([1]攻守數據!AK78 = "", "", [1]攻守數據!AK78) -> 49.248
... A120: =IF([1]攻守數據!AG121 = "", "", [1]攻守數據!AG121) | B120: =IF([1]攻守數據!AH121 = "", "", [1]攻守數據!AH121) | C120: =IF([1]攻守數據!AI121 = "", "", [1]攻守數據!AI121) | D120: =IF([1]攻守數據!AJ121 = "", "", [1]攻守數據!AJ121) | E120: =IF([1]攻守數據!AK121 = "", "", [1]攻守數據!AK121)
...
