Workbook

Sheet 工作表1
A1: 寶可夢 | B1: 屬性 | C1: DPS | E1: 攻/守 | F1: 一般 | G1: 火 | H1: 格鬥 | I1: 水 | J1: 飛行 | K1: 草 | L1: 毒 | M1: 電 | N1: 地面 | O1: 超能力 | P1: 岩石 | Q1: 冰 | R1: 蟲 | S1: 龍 | T1: 幽靈 | U1: 惡 | V1: 鋼 | W1: 妖精 | X1: 無
A2: =[1]屬性克制表!AQ2 -> Mega火焰雞 | B2: =[1]屬性克制表!AO2 -> 火 | C2: =[1]屬性克制表!AS2 -> 23.82 | E2: 一般 | F2: 1 | G2: 1 | H2: 1 | I2: 1 | J2: 1 | K2: 1 | L2: 1 | M2: 1 | N2: 1 | O2: 1 | P2: 0.625 | Q2: 1 | R2: 1 | S2: 1 | T2: 0.391 | U2: 1 | V2: 0.625 | W2: 1 | X2: 1
A3: =[1]屬性克制表!AQ3 -> Mega噴火龍Y | B3: =[1]屬性克制表!AO3 -> 火 | C3: =[1]屬性克制表!AS3 -> 22.78 | E3: 火 | F3: 1 | G3: 0.625 | H3: 1 | I3: 0.625 | J3: 1 | K3: 1.6 | L3: 1 | M3: 1 | N3: 1 | O3: 1 | P3: 0.625 | Q3: 1.6 | R3: 1.6 | S3: 0.625 | T3: 1 | U3: 1 | V3: 1.6 | W3: 1 | X3: 1
A4: =[1]屬性克制表!AQ4 -> 暗影萊希拉姆 | B4: =[1]屬性克制表!AO4 -> 火 | C4: =[1]屬性克制表!AS4 -> 23.59 | E4: 格鬥 | F4: 1.6 | G4: 1 | H4: 1 | I4: 1 | J4: 0.625 | K4: 1 | L4: 0.625 | M4: 1 | N4: 1 | O4: 0.625 | P4: 1.6 | Q4: 1.6 | R4: 0.625 | S4: 1 | T4: 0.391 | U4: 1.6 | V4: 1.6 | W4: 0.625 | X4: 1
A5: =[1]屬性克制表!AQ5 -> 萊希拉姆 | B5: =[1]屬性克制表!AO5 -> 火 | C5: =[1]屬性克制表!AS5 -> 19.58 | E5: 水 | F5: 1 | G5: 1.6 | H5: 1 | I5: 0.625 | J5: 1 | K5: 0.625 | L5: 1 | M5: 1 | N5: 1.6 | O5: 1 | P5: 1.6 | Q5: 1 | R5: 1 | S5: 0.625 | T5: 1 | U5: 1 | V5: 1 | W5: 1 | X5: 1
A6: =[1]屬性克制表!AQ6 -> Mega噴火龍X | B6: =[1]屬性克制表!AO6 -> 火 | C6: =[1]屬性克制表!AS6 -> 19.68 | E6: 飛行 | F6: 1 | G6: 1 | H6: 1.6 | I6: 1 | J6: 1 | K6: 1.6 | L6: 1 | M6: 0.625 | N6: 1 | O6: 1 | P6: 0.625 | Q6: 1 | R6: 1.6 | S6: 1 | T6: 1 | U6: 1 | V6: 0.625 | W6: 1 | X6: 1
A7: =[1]屬性克制表!AQ7 -> 暗影火焰雞 | B7: =[1]屬性克制表!AO7 -> 火 | C7: =[1]屬性克制表!AS7 -> 21.88 | E7: 草 | F7: 1 | G7: 0.625 | H7: 1 | I7: 1.6 | J7: 0.625 | K7: 0.625 | L7: 0.625 | M7: 1 | N7: 1.6 | O7: 1 | P7: 1.6 | Q7: 1 | R7: 0.625 | S7: 0.625 | T7: 1 | U7: 1 | V7: 0.625 | W7: 1 | X7: 1
A8: =[1]屬性克制表!AQ8 -> 砰頭小丑 | B8: =[1]屬性克制表!AO8 -> 火 | C8: =[1]屬性克制表!AS8 -> 24.81 | E8: 毒 | F8: 1 | G8: 1 | H8: 1 | I8: 1 | J8: 1 | K8: 1.6 | L8: 0.625 | M8: 1 | N8: 0.625 | O8: 1 | P8: 0.625 | Q8: 1 | R8: 1 | S8: 1 | T8: 0.625 | U8: 1 | V8: 0.391 | W8: 1.6 | X8: 1
A9: =[1]屬性克制表!AQ9 -> 暗影鳳王 | B9: =[1]屬性克制表!AO9 -> 火 | C9: =[1]屬性克制表!AS9 -> 18.52 | E9: 電 | F9: 1 | G9: 1 | H9: 1 | I9: 1.6 | J9: 1.6 | K9: 0.625 | L9: 1 | M9: 0.625 | N9: 0.391 | O9: 1 | P9: 1 | Q9: 1 | R9: 1 | S9: 0.625 | T9: 1 | U9: 1 | V9: 1 | W9: 1 | X9: 1
A10: =[1]屬性克制表!AQ10 -> 暗影席多藍恩 | B10: =[1]屬性克制表!AO10 -> 火 | C10: =[1]屬性克制表!AS10 -> 20.82 | E10: 地面 | F10: 1 | G10: 1.6 | H10: 1 | I10: 1 | J10: 0.391 | K10: 0.625 | L10: 1.6 | M10: 1.6 | N10: 1 | O10: 1 | P10: 1.6 | Q10: 1 | R10: 0.625 | S10: 1 | T10: 1 | U10: 1 | V10: 1.6 | W10: 1 | X10: 1
A11: =[1]屬性克制表!AQ11 -> 席多藍恩 | B11: =[1]屬性克制表!AO11 -> 火 | C11: =[1]屬性克制表!AS11 -> 17.18 | E11: 超能力 | F11: 1 | G11: 1 | H11: 1.6 | I11: 1 | J11: 1 | K11: 1 | L11: 1.6 | M11: 1 | N11: 1 | O11: 0.625 | P11: 1 | Q11: 1 | R11: 1 | S11: 1 | T11: 1 | U11: 0.391 | V11: 0.625 | W11: 1 | X11: 1
A12: =[1]屬性克制表!AQ12 -> Mega妖火紅狐 | B12: =[1]屬性克制表!AO12 -> 火 | C12: =[1]屬性克制表!AS12 -> 26.43 | E12: 岩石 | F12: 1 | G12: 1.6 | H12: 0.625 | I12: 1 | J12: 1.6 | K12: 1 | L12: 1 | M12: 1 | N12: 0.625 | O12: 1 | P12: 1 | Q12: 1.6 | R12: 1.6 | S12: 1 | T12: 1 | U12: 1 | V12: 0.625 | W12: 1 | X12: 1
A13: =[1]屬性克制表!AQ13 -> 噴火龍 | B13: =[1]屬性克制表!AO13 -> 火 | C13: =[1]屬性克制表!AS13 -> 16.53 | E13: 冰 | F13: 1 | G13: 0.625 | H13: 1 | I13: 0.625 | J13: 1.6 | K13: 1.6 | L13: 1 | M13: 1 | N13: 1.6 | O13: 1 | P13: 1 | Q13: 0.625 | R13: 1 | S13: 1.6 | T13: 1 | U13: 1 | V13: 0.625 | W13: 1 | X13: 1
... A20: =[1]屬性克制表!AQ20 -> 代拉基翁 | B20: =[1]屬性克制表!AO20 -> 格鬥 | C20: =[1]屬性克制表!AS20 -> 19.31 | E20: 無 | F20: 1 | G20: 1 | H20: 1 | I20: 1 | J20: 1 | K20: 1 | L20: 1 | M20: 1 | N20: 1 | O20: 1 | P20: 1 | Q20: 1 | R20: 1 | S20: 1 | T20: 1 | U20: 1 | V20: 1 | W20: 1 | X20: 1
A21: =[1]屬性克制表!AQ21 -> 路卡利歐 | B21: =[1]屬性克制表!AO21 -> 格鬥 | C21: =[1]屬性克制表!AS21 -> 20.88
A22: =[1]屬性克制表!AQ22 -> Mega列陣兵 | B22: =[1]屬性克制表!AO22 -> 格鬥 | C22: =[1]屬性克制表!AS22 -> 16.4
A23: =[1]屬性克制表!AQ23 -> 怪力 | B23: =[1]屬性克制表!AO23 -> 格鬥 | C23: =[1]屬性克制表!AS23 -> 16.95
A24: =[1]屬性克制表!AQ24 -> 鐵掌力士 | B24: =[1]屬性克制表!AO24 -> 格鬥 | C24: =[1]屬性克制表!AS24 -> 15.5
A25: =[1]屬性克制表!AQ25 -> Mega艾路雷朵 | B25: =[1]屬性克制表!AO25 -> 格鬥 | C25: =[1]屬性克制表!AS25 -> 17.69
A26: =[1]屬性克制表!AQ26 -> 勾帕路翁 | B26: =[1]屬性克制表!AO26 -> 格鬥 | C26: =[1]屬性克制表!AS26 -> 14.49
A27: =[1]屬性克制表!AQ27 -> 畢力吉翁 | B27: =[1]屬性克制表!AO27 -> 格鬥 | C27: =[1]屬性克制表!AS27 -> 14.49
A28: =[1]屬性克制表!AQ28 -> 艾路雷朵 | B28: =[1]屬性克制表!AO28 -> 格鬥 | C28: =[1]屬性克制表!AS28 -> 13.34
A29: =[1]屬性克制表!AQ29 -> 爆肌蚊 | B29: =[1]屬性克制表!AO29 -> 格鬥 | C29: =[1]屬性克制表!AS29 -> 14.84
A30: =[1]屬性克制表!AQ30 -> 原始蓋歐卡 | B30: =[1]屬性克制表!AO30 -> 水 | C30: =[1]屬性克制表!AS30 -> 22.2
A31: =[1]屬性克制表!AQ31 -> 暗影蓋歐卡 | B31: =[1]屬性克制表!AO31 -> 水 | C31: =[1]屬性克制表!AS31 -> 20.88
A32: =[1]屬性克制表!AQ32 -> Mega巨沼怪 | B32: =[1]屬性克制表!AO32 -> 水 | C32: =[1]屬性克制表!AS32 -> 19.94
... A75: =[1]屬性克制表!AQ75 -> 四顎針龍 | B75: =[1]屬性克制表!AO75 -> 毒 | C75: =[1]屬性克制表!AS75 -> 17.66
A76: =IF([1]屬性克制表!AQ76 = "", "", [1]屬性克制表!AQ76) -> 萬針魚 | B76: =[1]屬性克制表!AO76 -> 毒 | C76: =IF([1]屬性克制表!AS76 = "", "", [1]屬性克制表!AS76) -> 15.11
A77: =IF([1]屬性克制表!AQ77 = "", "", [1]屬性克制表!AQ77) -> 毒骷蛙 | B77: =[1]屬性克制表!AO77 -> 毒 | C77: =IF([1]屬性克制表!AS77 = "", "", [1]屬性克制表!AS77) -> 14.66
A78: =IF([1]屬性克制表!AQ78 = "", "", [1]屬性克制表!AQ78) -> 捷拉奧拉 | B78: =[1]屬性克制表!AO78 -> 電 | C78: =IF([1]屬性克制表!AS78 = "", "", [1]屬性克制表!AS78) -> 20.02
A79: =IF([1]屬性克制表!AQ79 = "", "", [1]屬性克制表!AQ79) -> Mega雷丘Y | B79: =[1]屬性克制表!AO79 -> 電 | C79: =IF([1]屬性克制表!AS79 = "", "", [1]屬性克制表!AS79) -> 27.27
A80: =IF([1]屬性克制表!AQ80 = "", "", [1]屬性克制表!AQ80) -> Mega雷丘X | B80: =[1]屬性克制表!AO80 -> 電 | C80: =IF([1]屬性克制表!AS80 = "", "", [1]屬性克制表!AS80) -> 23.55
A81: =IF([1]屬性克制表!AQ81 = "", "", [1]屬性克制表!AQ81) -> 暗影雷公 | B81: =[1]屬性克制表!AO81 -> 電 | C81: =IF([1]屬性克制表!AS81 = "", "", [1]屬性克制表!AS81) -> 20.05
A82: =IF([1]屬性克制表!AQ82 = "", "", [1]屬性克制表!AQ82) -> 雷電雲-靈獸形態 | B82: =[1]屬性克制表!AO82 -> 電 | C82: =IF([1]屬性克制表!AS82 = "", "", [1]屬性克制表!AS82) -> 19.9
A83: =IF([1]屬性克制表!AQ83 = "", "", [1]屬性克制表!AQ83) -> Mega雷電獸 | B83: =[1]屬性克制表!AO83 -> 電 | C83: =IF([1]屬性克制表!AS83 = "", "", [1]屬性克制表!AS83) -> 19.61
A84: =IF([1]屬性克制表!AQ84 = "", "", [1]屬性克制表!AQ84) -> Mega電龍 | B84: =[1]屬性克制表!AO84 -> 電 | C84: =IF([1]屬性克制表!AS84 = "", "", [1]屬性克制表!AS84) -> 17.29
A85: =IF([1]屬性克制表!AQ85 = "", "", [1]屬性克制表!AQ85) -> 電擊魔獸 | B85: =[1]屬性克制表!AO85 -> 電 | C85: =IF([1]屬性克制表!AS85 = "", "", [1]屬性克制表!AS85) -> 17.2
A86: =IF([1]屬性克制表!AQ86 = "", "", [1]屬性克制表!AQ86) -> 閃電鳥 | B86: =[1]屬性克制表!AO86 -> 電 | C86: =IF([1]屬性克制表!AS86 = "", "", [1]屬性克制表!AS86) -> 15.91
A87: =IF([1]屬性克制表!AQ87 = "", "", [1]屬性克制表!AQ87) -> 自爆磁怪 | B87: =[1]屬性克制表!AO87 -> 電 | C87: =IF([1]屬性克制表!AS87 = "", "", [1]屬性克制表!AS87) -> 15.81
... A212: =IF([1]屬性克制表!AQ212 = "", "", [1]屬性克制表!AQ212) -> 眷戀雲靈獸形態 | B212: =[1]屬性克制表!AO212 -> 妖精 | C212: =IF([1]屬性克制表!AS212 = "", "", [1]屬性克制表!AS212) -> 13.82
...
