Workbook

Sheet 攻守數據
A1: 格鬥 | C1: 地面 | E1: 水 | G1: 妖精 | K1: 屬性 | L1: 格鬥 | M1: 草
A2: 寶可夢 | B2: 抗性防禦 | C2: 寶可夢 | D2: 抗性防禦 | E2: 寶可夢 | F2: 抗性防禦 | G2: 寶可夢 | H2: 抗性防禦 | J2: 寶可夢 | K2: 屬性 | L2: 屬修 | M2: 基礎攻擊 | N2: 超級巨/極巨 | O2: 輸出 | Y2: 寶可夢 | Z2: 屬性一 | AA2: 屬性二 | AB2: 基礎防禦 | AD2: 寶可夢 | AE2: 屬性 | AF2: 屬修 | AG2: 基礎攻擊 | AH2: 超級巨/極巨 | AI2: 輸出 | AK2: 寶可夢 | AL2: 抗性防禦 | AM2: 寶可夢 | AN2: 抗性防禦 | AO2: 寶可夢 | AP2: 抗性防禦 | AQ2: 寶可夢 | AR2: 抗性防禦
A3: {=_xlfn.SORTBY(AK3:AL65, AL3:AL65, -1)} -> 洛奇亞 | B3: 129.61024 | C3: {=_xlfn.SORTBY(AM3:AN65, AN3:AN65, -1)} -> 洛奇亞 | D3: 129.48593 | E3: {=_xlfn.SORTBY(AO3:AP65, AP3:AP65, -1)} -> 幸福蛋 | F3: 61.686 | G3: {=_xlfn.SORTBY(AQ3:AR65, AR3:AR65, -1)} -> 藏瑪然特 | H3: 68.912 | J3: {=_xlfn.SORTBY(AD3:AI116, AI3:AI116, -1)} -> 閃電鳥 | K3: 飛行 | L3: Y | M3: 203 | N3: D | O3: 218265.6 | P3: =O3/$O$3 -> 1 | Y3: 幸福蛋 | Z3: 一般 | AA3: 無 | AB3: =AC4 -> 61.686 | AD3: 轟擂金剛猩 | AE3: 草 | AF3: Y | AG3: =AJ3 -> 200 | AH3: G | AI3: =AG3*IF(AH3="G", 450, IF(AH3="D", 350, 0)) * IF(AF3="Y", 1.2, 1)*(INDEX(屬性克制表!$B$2:$T$20, MATCH(AE3, 屬性克制表!$A$2:$A$20, 0), MATCH($L$1, 屬性克制表!$B$1:$T$1, 0)) * INDEX(屬性克制表!$B$2:$T$20, MATCH(AE3, 屬性克制表!$A$2:$A$20, 0), MATCH($M$1, 屬性克制表!$B$1:$T$1, 0))) -> 67500 | AJ3: =_xlfn.XLOOKUP(AD3, 數據!B$2:B$50, 數據!M$2:M$50) -> 200 | AK3: 幸福蛋 | AL3: =AB3/(INDEX(屬性克制表!$B$2:$T$20, MATCH($A$1, 屬性克制表!$A$2:$A$20, 0), MATCH(Z3, 屬性克制表!$B$1:$T$1, 0)) * INDEX(屬性克制表!$B$2:$T$20, MATCH($A$1, 屬性克制表!$A$2:$A$20, 0), MATCH(AA3, 屬性克制表!$B$1:$T$1, 0))) -> 38.55375 | AM3: 幸福蛋 | AN3: =AB3/(INDEX(屬性克制表!$B$2:$T$20, MATCH($C$1, 屬性克制表!$A$2:$A$20, 0), MATCH(Z3, 屬性克制表!$B$1:$T$1, 0)) * INDEX(屬性克制表!$B$2:$T$20, MATCH($C$1, 屬性克制表!$A$2:$A$20, 0), MATCH(AA3, 屬性克制表!$B$1:$T$1, 0))) -> 61.686 | AO3: 幸福蛋 | AP3: =AB3/(INDEX(屬性克制表!$B$2:$T$20, MATCH($E$1, 屬性克制表!$A$2:$A$20, 0), MATCH(Z3, 屬性克制表!$B$1:$T$1, 0)) * INDEX(屬性克制表!$B$2:$T$20, MATCH($E$1, 屬性克制表!$A$2:$A$20, 0), MATCH(AA3, 屬性克制表!$B$1:$T$1, 0))) -> 61.686 | AQ3: 幸福蛋 | AR3: =AB3/(INDEX(屬性克制表!$B$2:$T$20, MATCH($G$1, 屬性克制表!$A$2:$A$20, 0), MATCH(Z3, 屬性克制表!$B$1:$T$1, 0)) * INDEX(屬性克制表!$B$2:$T$20, MATCH($G$1, 屬性克制表!$A$2:$A$20, 0), MATCH(AA3, 屬性克制表!$B$1:$T$1, 0))) -> 61.686
A4: 耿鬼 | B4: 74.573913 | C4: 急凍鳥 | D4: 78.015345 | E4: 無極汰那 | F4: 57.2832 | G4: 幸福蛋 | H4: 61.686 | J4: 火焰鳥 | K4: 飛行 | L4: Y | M4: 200 | N4: D | O4: 215040 | P4: =O4/$O$3 -> 0.98522167 | Y4: 藏瑪然特 | Z4: 鋼 | AA4: 格鬥 | AB4: =AC5 -> 43.07 | AC4: =數據!P2 -> 61.686 | AD4: 怪力 | AE4: 格鬥 | AF4: Y | AG4: =AJ4 -> 201 | AH4: G | AI4: =AG4*IF(AH4="G", 450, IF(AH4="D", 350, 0)) * IF(AF4="Y", 1.2, 1)*(INDEX(屬性克制表!$B$2:$T$20, MATCH(AE4, 屬性克制表!$A$2:$A$20, 0), MATCH($L$1, 屬性克制表!$B$1:$T$1, 0)) * INDEX(屬性克制表!$B$2:$T$20, MATCH(AE4, 屬性克制表!$A$2:$A$20, 0), MATCH($M$1, 屬性克制表!$B$1:$T$1, 0))) -> 108540 | AJ4: =_xlfn.XLOOKUP(AD4, 數據!B$2:B$50, 數據!M$2:M$50) -> 201 | AK4: 藏瑪然特 | AL4: =AB4/(INDEX(屬性克制表!$B$2:$T$20, MATCH($A$1, 屬性克制表!$A$2:$A$20, 0), MATCH(Z4, 屬性克制表!$B$1:$T$1, 0)) * INDEX(屬性克制表!$B$2:$T$20, MATCH($A$1, 屬性克制表!$A$2:$A$20, 0), MATCH(AA4, 屬性克制表!$B$1:$T$1, 0))) -> 26.91875 | AM4: 藏瑪然特 | AN4: =AB4/(INDEX(屬性克制表!$B$2:$T$20, MATCH($C$1, 屬性克制表!$A$2:$A$20, 0), MATCH(Z4, 屬性克制表!$B$1:$T$1, 0)) * INDEX(屬性克制表!$B$2:$T$20, MATCH($C$1, 屬性克制表!$A$2:$A$20, 0), MATCH(AA4, 屬性克制表!$B$1:$T$1, 0))) -> 26.91875 | AO4: 藏瑪然特 | AP4: =AB4/(INDEX(屬性克制表!$B$2:$T$20, MATCH($E$1, 屬性克制表!$A$2:$A$20, 0), MATCH(Z4, 屬性克制表!$B$1:$T$1, 0)) * INDEX(屬性克制表!$B$2:$T$20, MATCH($E$1, 屬性克制表!$A$2:$A$20, 0), MATCH(AA4, 屬性克制表!$B$1:$T$1, 0))) -> 43.07 | AQ4: 藏瑪然特 | AR4: =AB4/(INDEX(屬性克制表!$B$2:$T$20, MATCH($G$1, 屬性克制表!$A$2:$A$20, 0), MATCH(Z4, 屬性克制表!$B$1:$T$1, 0)) * INDEX(屬性克制表!$B$2:$T$20, MATCH($G$1, 屬性克制表!$A$2:$A$20, 0), MATCH(AA4, 屬性克制表!$B$1:$T$1, 0))) -> 68.912
A5: 沙奈朵 | B5: 61.6192 | C5: 巴大蝶 | D5: 64.765217 | E5: 水君 | F5: 55.328 | G5: 蒼響 | H5: 58.9584 | J5: 高傲雉雞 | K5: 飛行 | L5: Y | M5: 188 | N5: D | O5: 202137.6 | P5: =O5/$O$3 -> 0.92610837 | Y5: 卡比獸 | Z5: 一般 | AA5: 無 | AB5: =AC6 -> 33.768 | AC5: =數據!P3 -> 43.07 | AD5: 戰弦蠑螈 | AE5: 電 | AF5: Y | AG5: =AJ5 -> 188 | AH5: G | AI5: =AG5*IF(AH5="G", 450, IF(AH5="D", 350, 0)) * IF(AF5="Y", 1.2, 1)*(INDEX(屬性克制表!$B$2:$T$20, MATCH(AE5, 屬性克制表!$A$2:$A$20, 0), MATCH($L$1, 屬性克制表!$B$1:$T$1, 0)) * INDEX(屬性克制表!$B$2:$T$20, MATCH(AE5, 屬性克制表!$A$2:$A$20, 0), MATCH($M$1, 屬性克制表!$B$1:$T$1, 0))) -> 63450 | AJ5: =_xlfn.XLOOKUP(AD5, 數據!B$2:B$50, 數據!M$2:M$50) -> 188 | AK5: 卡比獸 | AL5: =AB5/(INDEX(屬性克制表!$B$2:$T$20, MATCH($A$1, 屬性克制表!$A$2:$A$20, 0), MATCH(Z5, 屬性克制表!$B$1:$T$1, 0)) * INDEX(屬性克制表!$B$2:$T$20, MATCH($A$1, 屬性克制表!$A$2:$A$20, 0), MATCH(AA5, 屬性克制表!$B$1:$T$1, 0))) -> 21.105 | AM5: 卡比獸 | AN5: =AB5/(INDEX(屬性克制表!$B$2:$T$20, MATCH($C$1, 屬性克制表!$A$2:$A$20, 0), MATCH(Z5, 屬性克制表!$B$1:$T$1, 0)) * INDEX(屬性克制表!$B$2:$T$20, MATCH($C$1, 屬性克制表!$A$2:$A$20, 0), MATCH(AA5, 屬性克制表!$B$1:$T$1, 0))) -> 33.768 | AO5: 卡比獸 | AP5: =AB5/(INDEX(屬性克制表!$B$2:$T$20, MATCH($E$1, 屬性克制表!$A$2:$A$20, 0), MATCH(Z5, 屬性克制表!$B$1:$T$1, 0)) * INDEX(屬性克制表!$B$2:$T$20, MATCH($E$1, 屬性克制表!$A$2:$A$20, 0), MATCH(AA5, 屬性克制表!$B$1:$T$1, 0))) -> 33.768 | AQ5: 卡比獸 | AR5: =AB5/(INDEX(屬性克制表!$B$2:$T$20, MATCH($G$1, 屬性克制表!$A$2:$A$20, 0), MATCH(Z5, 屬性克制表!$B$1:$T$1, 0)) * INDEX(屬性克制表!$B$2:$T$20, MATCH($G$1, 屬性克制表!$A$2:$A$20, 0), MATCH(AA5, 屬性克制表!$B$1:$T$1, 0))) -> 33.768
A6: 無極汰那 | B6: 57.2832 | C6: 幸福蛋 | D6: 61.686 | E6: 鐮刀盔 | F6: 54.20032 | G6: 洛奇亞 | H6: 50.629 | J6: 噴火龍 | K6: 飛行 | L6: Y | M6: 187 | N6: D | O6: 201062.4 | P6: =O6/$O$3 -> 0.92118227 | Y6: 水君 | Z6: 水 | AA6: 無 | AB6: =AC7 -> 34.58 | AC6: =數據!P4 -> 33.768 | AD6: 妙蛙花 | AE6: 草 | AF6: Y | AG6: =AJ6 -> 159 | AH6: G | AI6: =AG6*IF(AH6="G", 450, IF(AH6="D", 350, 0)) * IF(AF6="Y", 1.2, 1)*(INDEX(屬性克制表!$B$2:$T$20, MATCH(AE6, 屬性克制表!$A$2:$A$20, 0), MATCH($L$1, 屬性克制表!$B$1:$T$1, 0)) * INDEX(屬性克制表!$B$2:$T$20, MATCH(AE6, 屬性克制表!$A$2:$A$20, 0), MATCH($M$1, 屬性克制表!$B$1:$T$1, 0))) -> 53662.5 | AJ6: =_xlfn.XLOOKUP(AD6, 數據!B$2:B$50, 數據!M$2:M$50) -> 159 | AK6: 水君 | AL6: =AB6/(INDEX(屬性克制表!$B$2:$T$20, MATCH($A$1, 屬性克制表!$A$2:$A$20, 0), MATCH(Z6, 屬性克制表!$B$1:$T$1, 0)) * INDEX(屬性克制表!$B$2:$T$20, MATCH($A$1, 屬性克制表!$A$2:$A$20, 0), MATCH(AA6, 屬性克制表!$B$1:$T$1, 0))) -> 34.58 | AM6: 水君 | AN6: =AB6/(INDEX(屬性克制表!$B$2:$T$20, MATCH($C$1, 屬性克制表!$A$2:$A$20, 0), MATCH(Z6, 屬性克制表!$B$1:$T$1, 0)) * INDEX(屬性克制表!$B$2:$T$20, MATCH($C$1, 屬性克制表!$A$2:$A$20, 0), MATCH(AA6, 屬性克制表!$B$1:$T$1, 0))) -> 34.58 | AO6: 水君 | AP6: =AB6/(INDEX(屬性克制表!$B$2:$T$20, MATCH($E$1, 屬性克制表!$A$2:$A$20, 0), MATCH(Z6, 屬性克制表!$B$1:$T$1, 0)) * INDEX(屬性克制表!$B$2:$T$20, MATCH($E$1, 屬性克制表!$A$2:$A$20, 0), MATCH(AA6, 屬性克制表!$B$1:$T$1, 0))) -> 55.328 | AQ6: 水君 | AR6: =AB6/(INDEX(屬性克制表!$B$2:$T$20, MATCH($G$1, 屬性克制表!$A$2:$A$20, 0), MATCH(Z6, 屬性克制表!$B$1:$T$1, 0)) * INDEX(屬性克制表!$B$2:$T$20, MATCH($G$1, 屬性克制表!$A$2:$A$20, 0), MATCH(AA6, 屬性克制表!$B$1:$T$1, 0))) -> 34.58
A7: 布莉姆溫 | B7: 50.7904 | C7: 高傲雉雞 | D7: 51.969309 | E7: 拉普拉斯 | F7: 54.096 | G7: 鋼鎧鴉 | H7: 50.16 | J7: 閃焰王牌 | K7: 火 | L7: Y | M7: 205 | N7: G | O7: 177120 | P7: =O7/$O$3 -> 0.81148839 | Y7: 無極汰那 | Z7: 龍 | AA7: 毒 | AB7: =AC8 -> 35.802 | AC7: =數據!P5 -> 34.58 | AD7: 武道熊師(連) | AE7: 格鬥 | AF7: Y | AG7: =AJ7 -> 210 | AH7: D | AI7: =AG7*IF(AH7="G", 450, IF(AH7="D", 350, 0)) * IF(AF7="Y", 1.2, 1)*(INDEX(屬性克制表!$B$2:$T$20, MATCH(AE7, 屬性克制表!$A$2:$A$20, 0), MATCH($L$1, 屬性克制表!$B$1:$T$1, 0)) * INDEX(屬性克制表!$B$2:$T$20, MATCH(AE7, 屬性克制表!$A$2:$A$20, 0), MATCH($M$1, 屬性克制表!$B$1:$T$1, 0))) -> 88200 | AJ7: =_xlfn.XLOOKUP(AD7, 數據!B$2:B$50, 數據!M$2:M$50) -> 210 | AK7: 無極汰那 | AL7: =AB7/(INDEX(屬性克制表!$B$2:$T$20, MATCH($A$1, 屬性克制表!$A$2:$A$20, 0), MATCH(Z7, 屬性克制表!$B$1:$T$1, 0)) * INDEX(屬性克制表!$B$2:$T$20, MATCH($A$1, 屬性克制表!$A$2:$A$20, 0), MATCH(AA7, 屬性克制表!$B$1:$T$1, 0))) -> 57.2832 | AM7: 無極汰那 | AN7: =AB7/(INDEX(屬性克制表!$B$2:$T$20, MATCH($C$1, 屬性克制表!$A$2:$A$20, 0), MATCH(Z7, 屬性克制表!$B$1:$T$1, 0)) * INDEX(屬性克制表!$B$2:$T$20, MATCH($C$1, 屬性克制表!$A$2:$A$20, 0), MATCH(AA7, 屬性克制表!$B$1:$T$1, 0))) -> 22.37625 | AO7: 無極汰那 | AP7: =AB7/(INDEX(屬性克制表!$B$2:$T$20, MATCH($E$1, 屬性克制表!$A$2:$A$20, 0), MATCH(Z7, 屬性克制表!$B$1:$T$1, 0)) * INDEX(屬性克制表!$B$2:$T$20, MATCH($E$1, 屬性克制表!$A$2:$A$20, 0), MATCH(AA7, 屬性克制表!$B$1:$T$1, 0))) -> 57.2832 | AQ7: 無極汰那 | AR7: =AB7/(INDEX(屬性克制表!$B$2:$T$20, MATCH($G$1, 屬性克制表!$A$2:$A$20, 0), MATCH(Z7, 屬性克制表!$B$1:$T$1, 0)) * INDEX(屬性克制表!$B$2:$T$20, MATCH($G$1, 屬性克制表!$A$2:$A$20, 0), MATCH(AA7, 屬性克制表!$B$1:$T$1, 0))) -> 35.802
A8: 仙子伊布 | B8: 50.3776 | C8: 鋼鎧鴉 | D8: 50.111893 | E8: 水伊布 | F8: 51.152 | G8: 巨金怪 | H8: 48.6864 | J8: 噴火龍 | K8: 火 | L8: Y | M8: 187 | N8: G | O8: 161568 | P8: =O8/$O$3 -> 0.74023575 | Y8: 急凍鳥 | Z8: 冰 | AA8: 飛行 | AB8: =AC9 -> 30.504 | AC8: =數據!P6 -> 35.802 | AD8: 閃電鳥 | AE8: 電 | AF8: Y | AG8: =AJ8 -> 203 | AH8: D | AI8: =AG8*IF(AH8="G", 450, IF(AH8="D", 350, 0)) * IF(AF8="Y", 1.2, 1)*(INDEX(屬性克制表!$B$2:$T$20, MATCH(AE8, 屬性克制表!$A$2:$A$20, 0), MATCH($L$1, 屬性克制表!$B$1:$T$1, 0)) * INDEX(屬性克制表!$B$2:$T$20, MATCH(AE8, 屬性克制表!$A$2:$A$20, 0), MATCH($M$1, 屬性克制表!$B$1:$T$1, 0))) -> 53287.5 | AJ8: =_xlfn.XLOOKUP(AD8, 數據!B$2:B$50, 數據!M$2:M$50) -> 203 | AK8: 急凍鳥 | AL8: =AB8/(INDEX(屬性克制表!$B$2:$T$20, MATCH($A$1, 屬性克制表!$A$2:$A$20, 0), MATCH(Z8, 屬性克制表!$B$1:$T$1, 0)) * INDEX(屬性克制表!$B$2:$T$20, MATCH($A$1, 屬性克制表!$A$2:$A$20, 0), MATCH(AA8, 屬性克制表!$B$1:$T$1, 0))) -> 30.504 | AM8: 急凍鳥 | AN8: =AB8/(INDEX(屬性克制表!$B$2:$T$20, MATCH($C$1, 屬性克制表!$A$2:$A$20, 0), MATCH(Z8, 屬性克制表!$B$1:$T$1, 0)) * INDEX(屬性克制表!$B$2:$T$20, MATCH($C$1, 屬性克制表!$A$2:$A$20, 0), MATCH(AA8, 屬性克制表!$B$1:$T$1, 0))) -> 78.015345 | AO8: 急凍鳥 | AP8: =AB8/(INDEX(屬性克制表!$B$2:$T$20, MATCH($E$1, 屬性克制表!$A$2:$A$20, 0), MATCH(Z8, 屬性克制表!$B$1:$T$1, 0)) * INDEX(屬性克制表!$B$2:$T$20, MATCH($E$1, 屬性克制表!$A$2:$A$20, 0), MATCH(AA8, 屬性克制表!$B$1:$T$1, 0))) -> 30.504 | AQ8: 急凍鳥 | AR8: =AB8/(INDEX(屬性克制表!$B$2:$T$20, MATCH($G$1, 屬性克制表!$A$2:$A$20, 0), MATCH(Z8, 屬性克制表!$B$1:$T$1, 0)) * INDEX(屬性克制表!$B$2:$T$20, MATCH($G$1, 屬性克制表!$A$2:$A$20, 0), MATCH(AA8, 屬性克制表!$B$1:$T$1, 0))) -> 30.504
A9: 拉帝歐斯 | B9: 44.4928 | C9: 轟擂金剛猩 | D9: 43.2432 | E9: 洛奇亞 | F9: 50.629 | G9: 閃焰王牌 | H9: 38.976 | J9: 胡地 | K9: 超能力 | L9: Y | M9: 225 | N9: D | O9: 151200 | P9: =O9/$O$3 -> 0.69273399 | Y9: 拉普拉斯 | Z9: 水 | AA9: 冰 | AB9: =AC10 -> 33.81 | AC9: =數據!P7 -> 30.504 | AD9: 雷公 | AE9: 電 | AF9: Y | AG9: =AJ9 -> 194 | AH9: D | AI9: =AG9*IF(AH9="G", 450, IF(AH9="D", 350, 0)) * IF(AF9="Y", 1.2, 1)*(INDEX(屬性克制表!$B$2:$T$20, MATCH(AE9, 屬性克制表!$A$2:$A$20, 0), MATCH($L$1, 屬性克制表!$B$1:$T$1, 0)) * INDEX(屬性克制表!$B$2:$T$20, MATCH(AE9, 屬性克制表!$A$2:$A$20, 0), MATCH($M$1, 屬性克制表!$B$1:$T$1, 0))) -> 50925 | AJ9: =_xlfn.XLOOKUP(AD9, 數據!B$2:B$50, 數據!M$2:M$50) -> 194 | AK9: 拉普拉斯 | AL9: =AB9/(INDEX(屬性克制表!$B$2:$T$20, MATCH($A$1, 屬性克制表!$A$2:$A$20, 0), MATCH(Z9, 屬性克制表!$B$1:$T$1, 0)) * INDEX(屬性克制表!$B$2:$T$20, MATCH($A$1, 屬性克制表!$A$2:$A$20, 0), MATCH(AA9, 屬性克制表!$B$1:$T$1, 0))) -> 21.13125 | AM9: 拉普拉斯 | AN9: =AB9/(INDEX(屬性克制表!$B$2:$T$20, MATCH($C$1, 屬性克制表!$A$2:$A$20, 0), MATCH(Z9, 屬性克制表!$B$1:$T$1, 0)) * INDEX(屬性克制表!$B$2:$T$20, MATCH($C$1, 屬性克制表!$A$2:$A$20, 0), MATCH(AA9, 屬性克制表!$B$1:$T$1, 0))) -> 33.81 | AO9: 拉普拉斯 | AP9: =AB9/(INDEX(屬性克制表!$B$2:$T$20, MATCH($E$1, 屬性克制表!$A$2:$A$20, 0), MATCH(Z9, 屬性克制表!$B$1:$T$1, 0)) * INDEX(屬性克制表!$B$2:$T$20, MATCH($E$1, 屬性克制表!$A$2:$A$20, 0), MATCH(AA9, 屬性克制表!$B$1:$T$1, 0))) -> 54.096 | AQ9: 拉普拉斯 | AR9: =AB9/(INDEX(屬性克制表!$B$2:$T$20, MATCH($G$1, 屬性克制表!$A$2:$A$20, 0), MATCH(Z9, 屬性克制表!$B$1:$T$1, 0)) * INDEX(屬性克制表!$B$2:$T$20, MATCH($G$1, 屬性克制表!$A$2:$A$20, 0), MATCH(AA9, 屬性克制表!$B$1:$T$1, 0))) -> 33.81
A10: 閃電鳥 | B10: 40.5888 | C10: 葉伊布 | D10: 41.44 | E10: 武道熊師(連) | F10: 45.12 | G10: 火焰鳥 | H10: 38.0768 | J10: 鋼鎧鴉 | K10: 飛行 | L10: Y | M10: 140 | N10: D | O10: 150528 | P10: =O10/$O$3 -> 0.68965517 | Y10: 拉帝亞斯 | Z10: 龍 | AA10: 超能力 | AB10: =AC11 -> 22.308 | AC10: =數據!P8 -> 33.81 | AD10: 轟擂金剛猩 | AE10: 草 | AF10: Y | AG10: =AJ10 -> 200 | AH10: D | AI10: =AG10*IF(AH10="G", 450, IF(AH10="D", 350, 0)) * IF(AF10="Y", 1.2, 1)*(INDEX(屬性克制表!$B$2:$T$20, MATCH(AE10, 屬性克制表!$A$2:$A$20, 0), MATCH($L$1, 屬性克制表!$B$1:$T$1, 0)) * INDEX(屬性克制表!$B$2:$T$20, MATCH(AE10, 屬性克制表!$A$2:$A$20, 0), MATCH($M$1, 屬性克制表!$B$1:$T$1, 0))) -> 52500 | AJ10: =_xlfn.XLOOKUP(AD10, 數據!B$2:B$50, 數據!M$2:M$50) -> 200 | AK10: 拉帝亞斯 | AL10: =AB10/(INDEX(屬性克制表!$B$2:$T$20, MATCH($A$1, 屬性克制表!$A$2:$A$20, 0), MATCH(Z10, 屬性克制表!$B$1:$T$1, 0)) * INDEX(屬性克制表!$B$2:$T$20, MATCH($A$1, 屬性克制表!$A$2:$A$20, 0), MATCH(AA10, 屬性克制表!$B$1:$T$1, 0))) -> 35.6928 | AM10: 拉帝亞斯 | AN10: =AB10/(INDEX(屬性克制表!$B$2:$T$20, MATCH($C$1, 屬性克制表!$A$2:$A$20, 0), MATCH(Z10, 屬性克制表!$B$1:$T$1, 0)) * INDEX(屬性克制表!$B$2:$T$20, MATCH($C$1, 屬性克制表!$A$2:$A$20, 0), MATCH(AA10, 屬性克制表!$B$1:$T$1, 0))) -> 22.308 | AO10: 拉帝亞斯 | AP10: =AB10/(INDEX(屬性克制表!$B$2:$T$20, MATCH($E$1, 屬性克制表!$A$2:$A$20, 0), MATCH(Z10, 屬性克制表!$B$1:$T$1, 0)) * INDEX(屬性克制表!$B$2:$T$20, MATCH($E$1, 屬性克制表!$A$2:$A$20, 0), MATCH(AA10, 屬性克制表!$B$1:$T$1, 0))) -> 35.6928 | AQ10: 拉帝亞斯 | AR10: =AB10/(INDEX(屬性克制表!$B$2:$T$20, MATCH($G$1, 屬性克制表!$A$2:$A$20, 0), MATCH(Z10, 屬性克制表!$B$1:$T$1, 0)) * INDEX(屬性克制表!$B$2:$T$20, MATCH($G$1, 屬性克制表!$A$2:$A$20, 0), MATCH(AA10, 屬性克制表!$B$1:$T$1, 0))) -> 13.9425
A11: 巴大蝶 | B11: 40.51712 | C11: 閃電鳥 | D11: 40.549872 | E11: 水箭龜 | F11: 44.52 | G11: 妙蛙花 | H11: 37.9392 | J11: 拉帝歐斯 | K11: 超能力 | L11: Y | M11: 221 | N11: D | O11: 148512 | P11: =O11/$O$3 -> 0.68041872 | Y11: 蒼響 | Z11: 鋼 | AA11: 妖精 | AB11: =AC12 -> 36.849 | AC11: =數據!P9 -> 22.308 | AD11: 怪力 | AE11: 格鬥 | AF11: Y | AG11: =AJ11 -> 201 | AH11: D | AI11: =AG11*IF(AH11="G", 450, IF(AH11="D", 350, 0)) * IF(AF11="Y", 1.2, 1)*(INDEX(屬性克制表!$B$2:$T$20, MATCH(AE11, 屬性克制表!$A$2:$A$20, 0), MATCH($L$1, 屬性克制表!$B$1:$T$1, 0)) * INDEX(屬性克制表!$B$2:$T$20, MATCH(AE11, 屬性克制表!$A$2:$A$20, 0), MATCH($M$1, 屬性克制表!$B$1:$T$1, 0))) -> 84420 | AJ11: =_xlfn.XLOOKUP(AD11, 數據!B$2:B$50, 數據!M$2:M$50) -> 201 | AK11: 蒼響 | AL11: =AB11/(INDEX(屬性克制表!$B$2:$T$20, MATCH($A$1, 屬性克制表!$A$2:$A$20, 0), MATCH(Z11, 屬性克制表!$B$1:$T$1, 0)) * INDEX(屬性克制表!$B$2:$T$20, MATCH($A$1, 屬性克制表!$A$2:$A$20, 0), MATCH(AA11, 屬性克制表!$B$1:$T$1, 0))) -> 36.849 | AM11: 蒼響 | AN11: =AB11/(INDEX(屬性克制表!$B$2:$T$20, MATCH($C$1, 屬性克制表!$A$2:$A$20, 0), MATCH(Z11, 屬性克制表!$B$1:$T$1, 0)) * INDEX(屬性克制表!$B$2:$T$20, MATCH($C$1, 屬性克制表!$A$2:$A$20, 0), MATCH(AA11, 屬性克制表!$B$1:$T$1, 0))) -> 23.030625 | AO11: 蒼響 | AP11: =AB11/(INDEX(屬性克制表!$B$2:$T$20, MATCH($E$1, 屬性克制表!$A$2:$A$20, 0), MATCH(Z11, 屬性克制表!$B$1:$T$1, 0)) * INDEX(屬性克制表!$B$2:$T$20, MATCH($E$1, 屬性克制表!$A$2:$A$20, 0), MATCH(AA11, 屬性克制表!$B$1:$T$1, 0))) -> 36.849 | AQ11: 蒼響 | AR11: =AB11/(INDEX(屬性克制表!$B$2:$T$20, MATCH($G$1, 屬性克制表!$A$2:$A$20, 0), MATCH(Z11, 屬性克制表!$B$1:$T$1, 0)) * INDEX(屬性克制表!$B$2:$T$20, MATCH($G$1, 屬性克制表!$A$2:$A$20, 0), MATCH(AA11, 屬性克制表!$B$1:$T$1, 0))) -> 58.9584
A12: 心蝙蝠 | B12: 38.80448 | C12: 甜冷美后 | D12: 39.84 | E12: 拉帝歐斯 | F12: 44.4928 | G12: 龍頭地鼠 | H12: 37.904 | J12: 狒狒達摩 | K12: 火 | L12: Y | M12: 218 | N12: D | O12: 146496 | P12: =O12/$O$3 -> 0.67118227 | Y12: 巨金怪 | Z12: 鋼 | AA12: 超能力 | AB12: =AC13 -> 30.429 | AC12: =數據!P10 -> 36.849 | AD12: 戰弦蠑螈 | AE12: 電 | AF12: Y | AG12: =AJ12 -> 188 | AH12: D | AI12: =AG12*IF(AH12="G", 450, IF(AH12="D", 350, 0)) * IF(AF12="Y", 1.2, 1)*(INDEX(屬性克制表!$B$2:$T$20, MATCH(AE12, 屬性克制表!$A$2:$A$20, 0), MATCH($L$1, 屬性克制表!$B$1:$T$1, 0)) * INDEX(屬性克制表!$B$2:$T$20, MATCH(AE12, 屬性克制表!$A$2:$A$20, 0), MATCH($M$1, 屬性克制表!$B$1:$T$1, 0))) -> 49350 | AJ12: =_xlfn.XLOOKUP(AD12, 數據!B$2:B$50, 數據!M$2:M$50) -> 188 | AK12: 巨金怪 | AL12: =AB12/(INDEX(屬性克制表!$B$2:$T$20, MATCH($A$1, 屬性克制表!$A$2:$A$20, 0), MATCH(Z12, 屬性克制表!$B$1:$T$1, 0)) * INDEX(屬性克制表!$B$2:$T$20, MATCH($A$1, 屬性克制表!$A$2:$A$20, 0), MATCH(AA12, 屬性克制表!$B$1:$T$1, 0))) -> 30.429 | AM12: 巨金怪 | AN12: =AB12/(INDEX(屬性克制表!$B$2:$T$20, MATCH($C$1, 屬性克制表!$A$2:$A$20, 0), MATCH(Z12, 屬性克制表!$B$1:$T$1, 0)) * INDEX(屬性克制表!$B$2:$T$20, MATCH($C$1, 屬性克制表!$A$2:$A$20, 0), MATCH(AA12, 屬性克制表!$B$1:$T$1, 0))) -> 19.018125 | AO12: 巨金怪 | AP12: =AB12/(INDEX(屬性克制表!$B$2:$T$20, MATCH($E$1, 屬性克制表!$A$2:$A$20, 0), MATCH(Z12, 屬性克制表!$B$1:$T$1, 0)) * INDEX(屬性克制表!$B$2:$T$20, MATCH($E$1, 屬性克制表!$A$2:$A$20, 0), MATCH(AA12, 屬性克制表!$B$1:$T$1, 0))) -> 30.429 | AQ12: 巨金怪 | AR12: =AB12/(INDEX(屬性克制表!$B$2:$T$20, MATCH($G$1, 屬性克制表!$A$2:$A$20, 0), MATCH(Z12, 屬性克制表!$B$1:$T$1, 0)) * INDEX(屬性克制表!$B$2:$T$20, MATCH($G$1, 屬性克制表!$A$2:$A$20, 0), MATCH(AA12, 屬性克制表!$B$1:$T$1, 0))) -> 48.6864
A13: 幸福蛋 | B13: 38.55375 | C13: 心蝙蝠 | D13: 38.767263 | E13: 轟擂金剛猩 | F13: 43.2432 | G13: 炎帝 | H13: 37.6832 | J13: 太陽伊布 | K13: 超能力 | L13: Y | M13: 218 | N13: D | O13: 146496 | P13: =O13/$O$3 -> 0.67118227 | Y13: 炎帝 | Z13: 火 | AA13: 無 | AB13: =AC14 -> 23.552 | AC13: =數據!P12 -> 30.429 | AD13: 投擲猴 | AE13: 格鬥 | AF13: Y | AG13: =AJ13 -> 181 | AH13: D | AI13: =AG13*IF(AH13="G", 450, IF(AH13="D", 350, 0)) * IF(AF13="Y", 1.2, 1)*(INDEX(屬性克制表!$B$2:$T$20, MATCH(AE13, 屬性克制表!$A$2:$A$20, 0), MATCH($L$1, 屬性克制表!$B$1:$T$1, 0)) * INDEX(屬性克制表!$B$2:$T$20, MATCH(AE13, 屬性克制表!$A$2:$A$20, 0), MATCH($M$1, 屬性克制表!$B$1:$T$1, 0))) -> 76020 | AJ13: =_xlfn.XLOOKUP(AD13, 數據!B$2:B$50, 數據!M$2:M$50) -> 181 | AK13: 炎帝 | AL13: =AB13/(INDEX(屬性克制表!$B$2:$T$20, MATCH($A$1, 屬性克制表!$A$2:$A$20, 0), MATCH(Z13, 屬性克制表!$B$1:$T$1, 0)) * INDEX(屬性克制表!$B$2:$T$20, MATCH($A$1, 屬性克制表!$A$2:$A$20, 0), MATCH(AA13, 屬性克制表!$B$1:$T$1, 0))) -> 23.552 | AM13: 炎帝 | AN13: =AB13/(INDEX(屬性克制表!$B$2:$T$20, MATCH($C$1, 屬性克制表!$A$2:$A$20, 0), MATCH(Z13, 屬性克制表!$B$1:$T$1, 0)) * INDEX(屬性克制表!$B$2:$T$20, MATCH($C$1, 屬性克制表!$A$2:$A$20, 0), MATCH(AA13, 屬性克制表!$B$1:$T$1, 0))) -> 14.72 | AO13: 炎帝 | AP13: =AB13/(INDEX(屬性克制表!$B$2:$T$20, MATCH($E$1, 屬性克制表!$A$2:$A$20, 0), MATCH(Z13, 屬性克制表!$B$1:$T$1, 0)) * INDEX(屬性克制表!$B$2:$T$20, MATCH($E$1, 屬性克制表!$A$2:$A$20, 0), MATCH(AA13, 屬性克制表!$B$1:$T$1, 0))) -> 14.72 | AQ13: 炎帝 | AR13: =AB13/(INDEX(屬性克制表!$B$2:$T$20, MATCH($G$1, 屬性克制表!$A$2:$A$20, 0), MATCH(Z13, 屬性克制表!$B$1:$T$1, 0)) * INDEX(屬性克制表!$B$2:$T$20, MATCH($G$1, 屬性克制表!$A$2:$A$20, 0), MATCH(AA13, 屬性克制表!$B$1:$T$1, 0))) -> 37.6832
A14: 艾路雷朵 | B14: 38.512 | C14: 火焰鳥 | D14: 38.040281 | E14: 藏瑪然特 | F14: 43.07 | G14: 灰塵山 | H14: 36.288 | J14: 巨金怪 | K14: 超能力 | L14: Y | M14: 214 | N14: D | O14: 143808 | P14: =O14/$O$3 -> 0.658867 | Y14: 鋼鎧鴉 | Z14: 鋼 | AA14: 飛行 | AB14: =AC15 -> 31.35 | AC14: =數據!P13 -> 23.552 | AD14: 耿鬼 | AE14: 幽靈 | AF14: Y | AG14: =AJ14 -> 223 | AH14: G | AI14: =AG14*IF(AH14="G", 450, IF(AH14="D", 350, 0)) * IF(AF14="Y", 1.2, 1)*(INDEX(屬性克制表!$B$2:$T$20, MATCH(AE14, 屬性克制表!$A$2:$A$20, 0), MATCH($L$1, 屬性克制表!$B$1:$T$1, 0)) * INDEX(屬性克制表!$B$2:$T$20, MATCH(AE14, 屬性克制表!$A$2:$A$20, 0), MATCH($M$1, 屬性克制表!$B$1:$T$1, 0))) -> 120420 | AJ14: =_xlfn.XLOOKUP(AD14, 數據!B$2:B$50, 數據!M$2:M$50) -> 223 | AK14: 鋼鎧鴉 | AL14: =AB14/(INDEX(屬性克制表!$B$2:$T$20, MATCH($A$1, 屬性克制表!$A$2:$A$20, 0), MATCH(Z14, 屬性克制表!$B$1:$T$1, 0)) * INDEX(屬性克制表!$B$2:$T$20, MATCH($A$1, 屬性克制表!$A$2:$A$20, 0), MATCH(AA14, 屬性克制表!$B$1:$T$1, 0))) -> 31.35 | AM14: 鋼鎧鴉 | AN14: =AB14/(INDEX(屬性克制表!$B$2:$T$20, MATCH($C$1, 屬性克制表!$A$2:$A$20, 0), MATCH(Z14, 屬性克制表!$B$1:$T$1, 0)) * INDEX(屬性克制表!$B$2:$T$20, MATCH($C$1, 屬性克制表!$A$2:$A$20, 0), MATCH(AA14, 屬性克制表!$B$1:$T$1, 0))) -> 50.111893 | AO14: 鋼鎧鴉 | AP14: =AB14/(INDEX(屬性克制表!$B$2:$T$20, MATCH($E$1, 屬性克制表!$A$2:$A$20, 0), MATCH(Z14, 屬性克制表!$B$1:$T$1, 0)) * INDEX(屬性克制表!$B$2:$T$20, MATCH($E$1, 屬性克制表!$A$2:$A$20, 0), MATCH(AA14, 屬性克制表!$B$1:$T$1, 0))) -> 31.35 | AQ14: 鋼鎧鴉 | AR14: =AB14/(INDEX(屬性克制表!$B$2:$T$20, MATCH($G$1, 屬性克制表!$A$2:$A$20, 0), MATCH(Z14, 屬性克制表!$B$1:$T$1, 0)) * INDEX(屬性克制表!$B$2:$T$20, MATCH($G$1, 屬性克制表!$A$2:$A$20, 0), MATCH(AA14, 屬性克制表!$B$1:$T$1, 0))) -> 50.16
A15: 火焰鳥 | B15: 38.0768 | C15: 月亮伊布 | D15: 36.764 | E15: 葉伊布 | F15: 41.44 | G15: 噴火龍 | H15: 36.192 | J15: 火伊布 | K15: 火 | L15: Y | M15: 206 | N15: D | O15: 138432 | P15: =O15/$O$3 -> 0.63423645 | Y15: 幾何雪花 | Z15: 冰 | AA15: 無 | AB15: =AC16 -> 26.296 | AC15: =數據!P14 -> 31.35 | AD15: 蒼響 | AE15: 鋼 | AF15: Y | AG15: =AJ15 -> 291 | AH15: D | AI15: =AG15*IF(AH15="G", 450, IF(AH15="D", 350, 0)) * IF(AF15="Y", 1.2, 1)*(INDEX(屬性克制表!$B$2:$T$20, MATCH(AE15, 屬性克制表!$A$2:$A$20, 0), MATCH($L$1, 屬性克制表!$B$1:$T$1, 0)) * INDEX(屬性克制表!$B$2:$T$20, MATCH(AE15, 屬性克制表!$A$2:$A$20, 0), MATCH($M$1, 屬性克制表!$B$1:$T$1, 0))) -> 122220 | AJ15: =_xlfn.XLOOKUP(AD15, 數據!B$2:B$50, 數據!M$2:M$50) -> 291 | AK15: 幾何雪花 | AL15: =AB15/(INDEX(屬性克制表!$B$2:$T$20, MATCH($A$1, 屬性克制表!$A$2:$A$20, 0), MATCH(Z15, 屬性克制表!$B$1:$T$1, 0)) * INDEX(屬性克制表!$B$2:$T$20, MATCH($A$1, 屬性克制表!$A$2:$A$20, 0), MATCH(AA15, 屬性克制表!$B$1:$T$1, 0))) -> 16.435 | AM15: 幾何雪花 | AN15: =AB15/(INDEX(屬性克制表!$B$2:$T$20, MATCH($C$1, 屬性克制表!$A$2:$A$20, 0), MATCH(Z15, 屬性克制表!$B$1:$T$1, 0)) * INDEX(屬性克制表!$B$2:$T$20, MATCH($C$1, 屬性克制表!$A$2:$A$20, 0), MATCH(AA15, 屬性克制表!$B$1:$T$1, 0))) -> 26.296 | AO15: 幾何雪花 | AP15: =AB15/(INDEX(屬性克制表!$B$2:$T$20, MATCH($E$1, 屬性克制表!$A$2:$A$20, 0), MATCH(Z15, 屬性克制表!$B$1:$T$1, 0)) * INDEX(屬性克制表!$B$2:$T$20, MATCH($E$1, 屬性克制表!$A$2:$A$20, 0), MATCH(AA15, 屬性克制表!$B$1:$T$1, 0))) -> 26.296 | AQ15: 幾何雪花 | AR15: =AB15/(INDEX(屬性克制表!$B$2:$T$20, MATCH($G$1, 屬性克制表!$A$2:$A$20, 0), MATCH(Z15, 屬性克制表!$B$1:$T$1, 0)) * INDEX(屬性克制表!$B$2:$T$20, MATCH($G$1, 屬性克制表!$A$2:$A$20, 0), MATCH(AA15, 屬性克制表!$B$1:$T$1, 0))) -> 26.296
A16: 妙蛙花 | B16: 37.9392 | C16: 噴火龍 | D16: 36.157289 | E16: 甜冷美后 | F16: 39.84 | G16: 超極巨灰塵山 | H16: 35.84 | J16: 閃焰王牌 | K16: 火 | L16: Y | M16: 205 | N16: D | O16: 137760 | P16: =O16/$O$3 -> 0.63115764 | Y16: 藏飽栗鼠 | Z16: 一般 | AA16: 無 | AB16: =AC17 -> 29.295 | AC16: =數據!P15 -> 26.296 | AD16: 多刺菊石獸 | AE16: 岩石 | AF16: Y | AG16: =AJ16 -> 177 | AH16: D | AI16: =AG16*IF(AH16="G", 450, IF(AH16="D", 350, 0)) * IF(AF16="Y", 1.2, 1)*(INDEX(屬性克制表!$B$2:$T$20, MATCH(AE16, 屬性克制表!$A$2:$A$20, 0), MATCH($L$1, 屬性克制表!$B$1:$T$1, 0)) * INDEX(屬性克制表!$B$2:$T$20, MATCH(AE16, 屬性克制表!$A$2:$A$20, 0), MATCH($M$1, 屬性克制表!$B$1:$T$1, 0))) -> 46462.5 | AJ16: =_xlfn.XLOOKUP(AD16, 數據!B$2:B$50, 數據!M$2:M$50) -> 177 | AK16: 藏飽栗鼠 | AL16: =AB16/(INDEX(屬性克制表!$B$2:$T$20, MATCH($A$1, 屬性克制表!$A$2:$A$20, 0), MATCH(Z16, 屬性克制表!$B$1:$T$1, 0)) * INDEX(屬性克制表!$B$2:$T$20, MATCH($A$1, 屬性克制表!$A$2:$A$20, 0), MATCH(AA16, 屬性克制表!$B$1:$T$1, 0))) -> 18.309375 | AM16: 藏飽栗鼠 | AN16: =AB16/(INDEX(屬性克制表!$B$2:$T$20, MATCH($C$1, 屬性克制表!$A$2:$A$20, 0), MATCH(Z16, 屬性克制表!$B$1:$T$1, 0)) * INDEX(屬性克制表!$B$2:$T$20, MATCH($C$1, 屬性克制表!$A$2:$A$20, 0), MATCH(AA16, 屬性克制表!$B$1:$T$1, 0))) -> 29.295 | AO16: 藏飽栗鼠 | AP16: =AB16/(INDEX(屬性克制表!$B$2:$T$20, MATCH($E$1, 屬性克制表!$A$2:$A$20, 0), MATCH(Z16, 屬性克制表!$B$1:$T$1, 0)) * INDEX(屬性克制表!$B$2:$T$20, MATCH($E$1, 屬性克制表!$A$2:$A$20, 0), MATCH(AA16, 屬性克制表!$B$1:$T$1, 0))) -> 29.295 | AQ16: 藏飽栗鼠 | AR16: =AB16/(INDEX(屬性克制表!$B$2:$T$20, MATCH($G$1, 屬性克制表!$A$2:$A$20, 0), MATCH(Z16, 屬性克制表!$B$1:$T$1, 0)) * INDEX(屬性克制表!$B$2:$T$20, MATCH($G$1, 屬性克制表!$A$2:$A$20, 0), MATCH(AA16, 屬性克制表!$B$1:$T$1, 0))) -> 29.295
A17: 蒼響 | B17: 36.849 | C17: 水君 | D17: 34.58 | E17: 妙蛙花 | F17: 37.9392 | G17: 無極汰那 | H17: 35.802 | J17: 烏賊王 | K17: 飛行 | L17: N | M17: 151 | N17: D | O17: 135296 | P17: =O17/$O$3 -> 0.61986864 | Y17: 雷公 | Z17: 電 | AA17: 無 | AB17: =AC18 -> 27.37 | AC17: =數據!P16 -> 29.295 | AD17: 妙蛙花 | AE17: 草 | AF17: Y | AG17: =AJ17 -> 159 | AH17: D | AI17: =AG17*IF(AH17="G", 450, IF(AH17="D", 350, 0)) * IF(AF17="Y", 1.2, 1)*(INDEX(屬性克制表!$B$2:$T$20, MATCH(AE17, 屬性克制表!$A$2:$A$20, 0), MATCH($L$1, 屬性克制表!$B$1:$T$1, 0)) * INDEX(屬性克制表!$B$2:$T$20, MATCH(AE17, 屬性克制表!$A$2:$A$20, 0), MATCH($M$1, 屬性克制表!$B$1:$T$1, 0))) -> 41737.5 | AJ17: =_xlfn.XLOOKUP(AD17, 數據!B$2:B$50, 數據!M$2:M$50) -> 159 | AK17: 雷公 | AL17: =AB17/(INDEX(屬性克制表!$B$2:$T$20, MATCH($A$1, 屬性克制表!$A$2:$A$20, 0), MATCH(Z17, 屬性克制表!$B$1:$T$1, 0)) * INDEX(屬性克制表!$B$2:$T$20, MATCH($A$1, 屬性克制表!$A$2:$A$20, 0), MATCH(AA17, 屬性克制表!$B$1:$T$1, 0))) -> 27.37 | AM17: 雷公 | AN17: =AB17/(INDEX(屬性克制表!$B$2:$T$20, MATCH($C$1, 屬性克制表!$A$2:$A$20, 0), MATCH(Z17, 屬性克制表!$B$1:$T$1, 0)) * INDEX(屬性克制表!$B$2:$T$20, MATCH($C$1, 屬性克制表!$A$2:$A$20, 0), MATCH(AA17, 屬性克制表!$B$1:$T$1, 0))) -> 17.10625 | AO17: 雷公 | AP17: =AB17/(INDEX(屬性克制表!$B$2:$T$20, MATCH($E$1, 屬性克制表!$A$2:$A$20, 0), MATCH(Z17, 屬性克制表!$B$1:$T$1, 0)) * INDEX(屬性克制表!$B$2:$T$20, MATCH($E$1, 屬性克制表!$A$2:$A$20, 0), MATCH(AA17, 屬性克制表!$B$1:$T$1, 0))) -> 27.37 | AQ17: 雷公 | AR17: =AB17/(INDEX(屬性克制表!$B$2:$T$20, MATCH($G$1, 屬性克制表!$A$2:$A$20, 0), MATCH(Z17, 屬性克制表!$B$1:$T$1, 0)) * INDEX(屬性克制表!$B$2:$T$20, MATCH($G$1, 屬性克制表!$A$2:$A$20, 0), MATCH(AA17, 屬性克制表!$B$1:$T$1, 0))) -> 27.37
A18: 灰塵山 | B18: 36.288 | C18: 拉普拉斯 | D18: 33.81 | E18: 鋁鋼龍 | F18: 37.1616 | G18: 水君 | H18: 34.58 | J18: 火焰鳥 | K18: 火 | L18: Y | M18: 200 | N18: D | O18: 134400 | P18: =O18/$O$3 -> 0.61576355 | Y18: 拉帝歐斯 | Z18: 龍 | AA18: 超能力 | AB18: =AC19 -> 27.808 | AC18: =數據!P17 -> 27.37 | AD18: 列陣兵 | AE18: 格鬥 | AF18: Y | AG18: =AJ18 -> 160 | AH18: D | AI18: =AG18*IF(AH18="G", 450, IF(AH18="D", 350, 0)) * IF(AF18="Y", 1.2, 1)*(INDEX(屬性克制表!$B$2:$T$20, MATCH(AE18, 屬性克制表!$A$2:$A$20, 0), MATCH($L$1, 屬性克制表!$B$1:$T$1, 0)) * INDEX(屬性克制表!$B$2:$T$20, MATCH(AE18, 屬性克制表!$A$2:$A$20, 0), MATCH($M$1, 屬性克制表!$B$1:$T$1, 0))) -> 67200 | AJ18: =_xlfn.XLOOKUP(AD18, 數據!B$2:B$50, 數據!M$2:M$50) -> 160 | AK18: 拉帝歐斯 | AL18: =AB18/(INDEX(屬性克制表!$B$2:$T$20, MATCH($A$1, 屬性克制表!$A$2:$A$20, 0), MATCH(Z18, 屬性克制表!$B$1:$T$1, 0)) * INDEX(屬性克制表!$B$2:$T$20, MATCH($A$1, 屬性克制表!$A$2:$A$20, 0), MATCH(AA18, 屬性克制表!$B$1:$T$1, 0))) -> 44.4928 | AM18: 拉帝歐斯 | AN18: =AB18/(INDEX(屬性克制表!$B$2:$T$20, MATCH($C$1, 屬性克制表!$A$2:$A$20, 0), MATCH(Z18, 屬性克制表!$B$1:$T$1, 0)) * INDEX(屬性克制表!$B$2:$T$20, MATCH($C$1, 屬性克制表!$A$2:$A$20, 0), MATCH(AA18, 屬性克制表!$B$1:$T$1, 0))) -> 27.808 | AO18: 拉帝歐斯 | AP18: =AB18/(INDEX(屬性克制表!$B$2:$T$20, MATCH($E$1, 屬性克制表!$A$2:$A$20, 0), MATCH(Z18, 屬性克制表!$B$1:$T$1, 0)) * INDEX(屬性克制表!$B$2:$T$20, MATCH($E$1, 屬性克制表!$A$2:$A$20, 0), MATCH(AA18, 屬性克制表!$B$1:$T$1, 0))) -> 44.4928 | AQ18: 拉帝歐斯 | AR18: =AB18/(INDEX(屬性克制表!$B$2:$T$20, MATCH($G$1, 屬性克制表!$A$2:$A$20, 0), MATCH(Z18, 屬性克制表!$B$1:$T$1, 0)) * INDEX(屬性克制表!$B$2:$T$20, MATCH($G$1, 屬性克制表!$A$2:$A$20, 0), MATCH(AA18, 屬性克制表!$B$1:$T$1, 0))) -> 17.38
A19: 噴火龍 | B19: 36.192 | C19: 卡比獸 | D19: 33.768 | E19: 蒼響 | F19: 36.849 | G19: 火伊布 | H19: 34.272 | J19: 冰伊布 | K19: 冰 | L19: Y | M19: 200 | N19: D | O19: 134400 | P19: =O19/$O$3 -> 0.61576355 | Y19: 武道熊師(連) | Z19: 格鬥 | AA19: 水 | AB19: =AC20 -> 28.2 | AC19: =數據!P11 -> 27.808 | AD19: 閃焰王牌 | AE19: 火 | AF19: Y | AG19: =AJ19 -> 205 | AH19: G | AI19: =AG19*IF(AH19="G", 450, IF(AH19="D", 350, 0)) * IF(AF19="Y", 1.2, 1)*(INDEX(屬性克制表!$B$2:$T$20, MATCH(AE19, 屬性克制表!$A$2:$A$20, 0), MATCH($L$1, 屬性克制表!$B$1:$T$1, 0)) * INDEX(屬性克制表!$B$2:$T$20, MATCH(AE19, 屬性克制表!$A$2:$A$20, 0), MATCH($M$1, 屬性克制表!$B$1:$T$1, 0))) -> 177120 | AJ19: =_xlfn.XLOOKUP(AD19, 數據!B$2:B$50, 數據!M$2:M$50) -> 205 | AK19: 武道熊師(連) | AL19: =AB19/(INDEX(屬性克制表!$B$2:$T$20, MATCH($A$1, 屬性克制表!$A$2:$A$20, 0), MATCH(Z19, 屬性克制表!$B$1:$T$1, 0)) * INDEX(屬性克制表!$B$2:$T$20, MATCH($A$1, 屬性克制表!$A$2:$A$20, 0), MATCH(AA19, 屬性克制表!$B$1:$T$1, 0))) -> 28.2 | AM19: 武道熊師(連) | AN19: =AB19/(INDEX(屬性克制表!$B$2:$T$20, MATCH($C$1, 屬性克制表!$A$2:$A$20, 0), MATCH(Z19, 屬性克制表!$B$1:$T$1, 0)) * INDEX(屬性克制表!$B$2:$T$20, MATCH($C$1, 屬性克制表!$A$2:$A$20, 0), MATCH(AA19, 屬性克制表!$B$1:$T$1, 0))) -> 28.2 | AO19: 武道熊師(連) | AP19: =AB19/(INDEX(屬性克制表!$B$2:$T$20, MATCH($E$1, 屬性克制表!$A$2:$A$20, 0), MATCH(Z19, 屬性克制表!$B$1:$T$1, 0)) * INDEX(屬性克制表!$B$2:$T$20, MATCH($E$1, 屬性克制表!$A$2:$A$20, 0), MATCH(AA19, 屬性克制表!$B$1:$T$1, 0))) -> 45.12 | AQ19: 武道熊師(連) | AR19: =AB19/(INDEX(屬性克制表!$B$2:$T$20, MATCH($G$1, 屬性克制表!$A$2:$A$20, 0), MATCH(Z19, 屬性克制表!$B$1:$T$1, 0)) * INDEX(屬性克制表!$B$2:$T$20, MATCH($G$1, 屬性克制表!$A$2:$A$20, 0), MATCH(AA19, 屬性克制表!$B$1:$T$1, 0))) -> 28.2
A20: 超極巨灰塵山 | B20: 35.84 | C20: 壺壺 | D20: 33.66 | E20: 月亮伊布 | F20: 36.764 | G20: 拉普拉斯 | H20: 33.81 | J20: 超極巨灰塵山 | K20: 毒 | L20: Y | M20: 155 | N20: G | O20: 133920 | P20: =O20/$O$3 -> 0.61356439 | Y20: 武道熊師(一) | Z20: 格鬥 | AA20: 惡 | AB20: =數據!P19 -> 28.2 | AC20: =數據!P18 -> 28.2 | AD20: 鐮刀盔 | AE20: 格鬥 | AF20: N | AG20: =AJ20 -> 185 | AH20: D | AI20: =AG20*IF(AH20="G", 450, IF(AH20="D", 350, 0)) * IF(AF20="Y", 1.2, 1)*(INDEX(屬性克制表!$B$2:$T$20, MATCH(AE20, 屬性克制表!$A$2:$A$20, 0), MATCH($L$1, 屬性克制表!$B$1:$T$1, 0)) * INDEX(屬性克制表!$B$2:$T$20, MATCH(AE20, 屬性克制表!$A$2:$A$20, 0), MATCH($M$1, 屬性克制表!$B$1:$T$1, 0))) -> 64750 | AJ20: =_xlfn.XLOOKUP(AD20, 數據!B$2:B$50, 數據!M$2:M$50) -> 185 | AK20: 武道熊師(一) | AL20: =AB20/(INDEX(屬性克制表!$B$2:$T$20, MATCH($A$1, 屬性克制表!$A$2:$A$20, 0), MATCH(Z20, 屬性克制表!$B$1:$T$1, 0)) * INDEX(屬性克制表!$B$2:$T$20, MATCH($A$1, 屬性克制表!$A$2:$A$20, 0), MATCH(AA20, 屬性克制表!$B$1:$T$1, 0))) -> 17.625 | AM20: 武道熊師(一) | AN20: =AB20/(INDEX(屬性克制表!$B$2:$T$20, MATCH($C$1, 屬性克制表!$A$2:$A$20, 0), MATCH(Z20, 屬性克制表!$B$1:$T$1, 0)) * INDEX(屬性克制表!$B$2:$T$20, MATCH($C$1, 屬性克制表!$A$2:$A$20, 0), MATCH(AA20, 屬性克制表!$B$1:$T$1, 0))) -> 28.2 | AO20: 武道熊師(一) | AP20: =AB20/(INDEX(屬性克制表!$B$2:$T$20, MATCH($E$1, 屬性克制表!$A$2:$A$20, 0), MATCH(Z20, 屬性克制表!$B$1:$T$1, 0)) * INDEX(屬性克制表!$B$2:$T$20, MATCH($E$1, 屬性克制表!$A$2:$A$20, 0), MATCH(AA20, 屬性克制表!$B$1:$T$1, 0))) -> 28.2 | AQ20: 武道熊師(一) | AR20: =AB20/(INDEX(屬性克制表!$B$2:$T$20, MATCH($G$1, 屬性克制表!$A$2:$A$20, 0), MATCH(Z20, 屬性克制表!$B$1:$T$1, 0)) * INDEX(屬性克制表!$B$2:$T$20, MATCH($G$1, 屬性克制表!$A$2:$A$20, 0), MATCH(AA20, 屬性克制表!$B$1:$T$1, 0))) -> 17.625
A21: 拉帝亞斯 | B21: 35.6928 | C21: 水伊布 | D21: 31.97 | E21: 吼鯨王 | F21: 36.608 | G21: 卡比獸 | H21: 33.768 | J21: 沙奈朵 | K21: 超能力 | L21: Y | M21: 199 | N21: D | O21: 133728 | P21: =O21/$O$3 -> 0.61268473 | Y21: 水箭龜 | Z21: 水 | AA21: 無 | AB21: =數據!P20 -> 27.825 | AC21: =數據!P19 -> 28.2 | AD21: 噴火龍 | AE21: 火 | AF21: Y | AG21: =AJ21 -> 187 | AH21: G | AI21: =AG21*IF(AH21="G", 450, IF(AH21="D", 350, 0)) * IF(AF21="Y", 1.2, 1)*(INDEX(屬性克制表!$B$2:$T$20, MATCH(AE21, 屬性克制表!$A$2:$A$20, 0), MATCH($L$1, 屬性克制表!$B$1:$T$1, 0)) * INDEX(屬性克制表!$B$2:$T$20, MATCH(AE21, 屬性克制表!$A$2:$A$20, 0), MATCH($M$1, 屬性克制表!$B$1:$T$1, 0))) -> 161568 | AJ21: =_xlfn.XLOOKUP(AD21, 數據!B$2:B$50, 數據!M$2:M$50) -> 187 | AK21: 水箭龜 | AL21: =AB21/(INDEX(屬性克制表!$B$2:$T$20, MATCH($A$1, 屬性克制表!$A$2:$A$20, 0), MATCH(Z21, 屬性克制表!$B$1:$T$1, 0)) * INDEX(屬性克制表!$B$2:$T$20, MATCH($A$1, 屬性克制表!$A$2:$A$20, 0), MATCH(AA21, 屬性克制表!$B$1:$T$1, 0))) -> 27.825 | AM21: 水箭龜 | AN21: =AB21/(INDEX(屬性克制表!$B$2:$T$20, MATCH($C$1, 屬性克制表!$A$2:$A$20, 0), MATCH(Z21, 屬性克制表!$B$1:$T$1, 0)) * INDEX(屬性克制表!$B$2:$T$20, MATCH($C$1, 屬性克制表!$A$2:$A$20, 0), MATCH(AA21, 屬性克制表!$B$1:$T$1, 0))) -> 27.825 | AO21: 水箭龜 | AP21: =AB21/(INDEX(屬性克制表!$B$2:$T$20, MATCH($E$1, 屬性克制表!$A$2:$A$20, 0), MATCH(Z21, 屬性克制表!$B$1:$T$1, 0)) * INDEX(屬性克制表!$B$2:$T$20, MATCH($E$1, 屬性克制表!$A$2:$A$20, 0), MATCH(AA21, 屬性克制表!$B$1:$T$1, 0))) -> 44.52 | AQ21: 水箭龜 | AR21: =AB21/(INDEX(屬性克制表!$B$2:$T$20, MATCH($G$1, 屬性克制表!$A$2:$A$20, 0), MATCH(Z21, 屬性克制表!$B$1:$T$1, 0)) * INDEX(屬性克制表!$B$2:$T$20, MATCH($G$1, 屬性克制表!$A$2:$A$20, 0), MATCH(AA21, 屬性克制表!$B$1:$T$1, 0))) -> 27.825
A22: 水君 | B22: 34.58 | C22: 仙子伊布 | D22: 31.486 | E22: 拉帝亞斯 | F22: 35.6928 | G22: 壺壺 | H22: 33.66 | J22: 艾路雷朵 | K22: 超能力 | L22: Y | M22: 199 | N22: D | O22: 133728 | P22: =O22/$O$3 -> 0.61268473 | Y22: 閃電鳥 | Z22: 電 | AA22: 飛行 | AB22: =數據!P21 -> 25.368 | AC22: =數據!P20 -> 27.825 | AD22: 無極汰那 | AE22: 龍 | AF22: Y | AG22: =AJ22 -> 229 | AH22: D | AI22: =AG22*IF(AH22="G", 450, IF(AH22="D", 350, 0)) * IF(AF22="Y", 1.2, 1)*(INDEX(屬性克制表!$B$2:$T$20, MATCH(AE22, 屬性克制表!$A$2:$A$20, 0), MATCH($L$1, 屬性克制表!$B$1:$T$1, 0)) * INDEX(屬性克制表!$B$2:$T$20, MATCH(AE22, 屬性克制表!$A$2:$A$20, 0), MATCH($M$1, 屬性克制表!$B$1:$T$1, 0))) -> 96180 | AJ22: =_xlfn.XLOOKUP(AD22, 數據!B$2:B$50, 數據!M$2:M$50) -> 229 | AK22: 閃電鳥 | AL22: =AB22/(INDEX(屬性克制表!$B$2:$T$20, MATCH($A$1, 屬性克制表!$A$2:$A$20, 0), MATCH(Z22, 屬性克制表!$B$1:$T$1, 0)) * INDEX(屬性克制表!$B$2:$T$20, MATCH($A$1, 屬性克制表!$A$2:$A$20, 0), MATCH(AA22, 屬性克制表!$B$1:$T$1, 0))) -> 40.5888 | AM22: 閃電鳥 | AN22: =AB22/(INDEX(屬性克制表!$B$2:$T$20, MATCH($C$1, 屬性克制表!$A$2:$A$20, 0), MATCH(Z22, 屬性克制表!$B$1:$T$1, 0)) * INDEX(屬性克制表!$B$2:$T$20, MATCH($C$1, 屬性克制表!$A$2:$A$20, 0), MATCH(AA22, 屬性克制表!$B$1:$T$1, 0))) -> 40.549872 | AO22: 閃電鳥 | AP22: =AB22/(INDEX(屬性克制表!$B$2:$T$20, MATCH($E$1, 屬性克制表!$A$2:$A$20, 0), MATCH(Z22, 屬性克制表!$B$1:$T$1, 0)) * INDEX(屬性克制表!$B$2:$T$20, MATCH($E$1, 屬性克制表!$A$2:$A$20, 0), MATCH(AA22, 屬性克制表!$B$1:$T$1, 0))) -> 25.368 | AQ22: 閃電鳥 | AR22: =AB22/(INDEX(屬性克制表!$B$2:$T$20, MATCH($G$1, 屬性克制表!$A$2:$A$20, 0), MATCH(Z22, 屬性克制表!$B$1:$T$1, 0)) * INDEX(屬性克制表!$B$2:$T$20, MATCH($G$1, 屬性克制表!$A$2:$A$20, 0), MATCH(AA22, 屬性克制表!$B$1:$T$1, 0))) -> 25.368
A23: 壺壺 | B23: 33.66 | C23: 藏飽栗鼠 | D23: 29.295 | E23: 卡比獸 | F23: 33.768 | G23: 水伊布 | H23: 31.97 | J23: 布莉姆溫 | K23: 超能力 | L23: Y | M23: 198 | N23: D | O23: 133056 | P23: =O23/$O$3 -> 0.60960591 | Y23: 轟擂金剛猩 | Z23: 草 | AA23: 無 | AB23: =數據!P22 -> 27.027 | AC23: =數據!P21 -> 25.368 | AD23: 拉帝歐斯 | AE23: 超能力 | AF23: Y | AG23: =AJ23 -> 221 | AH23: D | AI23: =AG23*IF(AH23="G", 450, IF(AH23="D", 350, 0)) * IF(AF23="Y", 1.2, 1)*(INDEX(屬性克制表!$B$2:$T$20, MATCH(AE23, 屬性克制表!$A$2:$A$20, 0), MATCH($L$1, 屬性克制表!$B$1:$T$1, 0)) * INDEX(屬性克制表!$B$2:$T$20, MATCH(AE23, 屬性克制表!$A$2:$A$20, 0), MATCH($M$1, 屬性克制表!$B$1:$T$1, 0))) -> 148512 | AJ23: =_xlfn.XLOOKUP(AD23, 數據!B$2:B$50, 數據!M$2:M$50) -> 221 | AK23: 轟擂金剛猩 | AL23: =AB23/(INDEX(屬性克制表!$B$2:$T$20, MATCH($A$1, 屬性克制表!$A$2:$A$20, 0), MATCH(Z23, 屬性克制表!$B$1:$T$1, 0)) * INDEX(屬性克制表!$B$2:$T$20, MATCH($A$1, 屬性克制表!$A$2:$A$20, 0), MATCH(AA23, 屬性克制表!$B$1:$T$1, 0))) -> 27.027 | AM23: 轟擂金剛猩 | AN23: =AB23/(INDEX(屬性克制表!$B$2:$T$20, MATCH($C$1, 屬性克制表!$A$2:$A$20, 0), MATCH(Z23, 屬性克制表!$B$1:$T$1, 0)) * INDEX(屬性克制表!$B$2:$T$20, MATCH($C$1, 屬性克制表!$A$2:$A$20, 0), MATCH(AA23, 屬性克制表!$B$1:$T$1, 0))) -> 43.2432 | AO23: 轟擂金剛猩 | AP23: =AB23/(INDEX(屬性克制表!$B$2:$T$20, MATCH($E$1, 屬性克制表!$A$2:$A$20, 0), MATCH(Z23, 屬性克制表!$B$1:$T$1, 0)) * INDEX(屬性克制表!$B$2:$T$20, MATCH($E$1, 屬性克制表!$A$2:$A$20, 0), MATCH(AA23, 屬性克制表!$B$1:$T$1, 0))) -> 43.2432 | AQ23: 轟擂金剛猩 | AR23: =AB23/(INDEX(屬性克制表!$B$2:$T$20, MATCH($G$1, 屬性克制表!$A$2:$A$20, 0), MATCH(Z23, 屬性克制表!$B$1:$T$1, 0)) * INDEX(屬性克制表!$B$2:$T$20, MATCH($G$1, 屬性克制表!$A$2:$A$20, 0), MATCH(AA23, 屬性克制表!$B$1:$T$1, 0))) -> 27.027
A24: 太陽伊布 | B24: 33.6 | C24: 武道熊師(連) | D24: 28.2 | E24: 仙子伊布 | F24: 31.486 | G24: 仙子伊布 | H24: 31.486 | J24: 戰弦蠑螈 | K24: 毒 | L24: Y | M24: 188 | N24: D | O24: 126336 | P24: =O24/$O$3 -> 0.57881773 | Y24: 火焰鳥 | Z24: 火 | AA24: 飛行 | AB24: =數據!P23 -> 23.798 | AC24: =數據!P22 -> 27.027 | AD24: 拉帝歐斯 | AE24: 龍 | AF24: Y | AG24: =AJ24 -> 221 | AH24: D | AI24: =AG24*IF(AH24="G", 450, IF(AH24="D", 350, 0)) * IF(AF24="Y", 1.2, 1)*(INDEX(屬性克制表!$B$2:$T$20, MATCH(AE24, 屬性克制表!$A$2:$A$20, 0), MATCH($L$1, 屬性克制表!$B$1:$T$1, 0)) * INDEX(屬性克制表!$B$2:$T$20, MATCH(AE24, 屬性克制表!$A$2:$A$20, 0), MATCH($M$1, 屬性克制表!$B$1:$T$1, 0))) -> 92820 | AJ24: =_xlfn.XLOOKUP(AD24, 數據!B$2:B$50, 數據!M$2:M$50) -> 221 | AK24: 火焰鳥 | AL24: =AB24/(INDEX(屬性克制表!$B$2:$T$20, MATCH($A$1, 屬性克制表!$A$2:$A$20, 0), MATCH(Z24, 屬性克制表!$B$1:$T$1, 0)) * INDEX(屬性克制表!$B$2:$T$20, MATCH($A$1, 屬性克制表!$A$2:$A$20, 0), MATCH(AA24, 屬性克制表!$B$1:$T$1, 0))) -> 38.0768 | AM24: 火焰鳥 | AN24: =AB24/(INDEX(屬性克制表!$B$2:$T$20, MATCH($C$1, 屬性克制表!$A$2:$A$20, 0), MATCH(Z24, 屬性克制表!$B$1:$T$1, 0)) * INDEX(屬性克制表!$B$2:$T$20, MATCH($C$1, 屬性克制表!$A$2:$A$20, 0), MATCH(AA24, 屬性克制表!$B$1:$T$1, 0))) -> 38.040281 | AO24: 火焰鳥 | AP24: =AB24/(INDEX(屬性克制表!$B$2:$T$20, MATCH($E$1, 屬性克制表!$A$2:$A$20, 0), MATCH(Z24, 屬性克制表!$B$1:$T$1, 0)) * INDEX(屬性克制表!$B$2:$T$20, MATCH($E$1, 屬性克制表!$A$2:$A$20, 0), MATCH(AA24, 屬性克制表!$B$1:$T$1, 0))) -> 14.87375 | AQ24: 火焰鳥 | AR24: =AB24/(INDEX(屬性克制表!$B$2:$T$20, MATCH($G$1, 屬性克制表!$A$2:$A$20, 0), MATCH(Z24, 屬性克制表!$B$1:$T$1, 0)) * INDEX(屬性克制表!$B$2:$T$20, MATCH($G$1, 屬性克制表!$A$2:$A$20, 0), MATCH(AA24, 屬性克制表!$B$1:$T$1, 0))) -> 38.0768
A25: 水伊布 | B25: 31.97 | C25: 武道熊師(一) | D25: 28.2 | E25: 鋼鎧鴉 | F25: 31.35 | G25: 狒狒達摩 | H25: 30.88 | J25: 噴火龍 | K25: 火 | L25: Y | M25: 187 | N25: D | O25: 125664 | P25: =O25/$O$3 -> 0.57573892 | Y25: 投擲猴 | Z25: 格鬥 | AA25: 無 | AB25: =數據!P24 -> 24.104 | AC25: =數據!P23 -> 23.798 | AD25: 狒狒達摩 | AE25: 火 | AF25: Y | AG25: =AJ25 -> 218 | AH25: D | AI25: =AG25*IF(AH25="G", 450, IF(AH25="D", 350, 0)) * IF(AF25="Y", 1.2, 1)*(INDEX(屬性克制表!$B$2:$T$20, MATCH(AE25, 屬性克制表!$A$2:$A$20, 0), MATCH($L$1, 屬性克制表!$B$1:$T$1, 0)) * INDEX(屬性克制表!$B$2:$T$20, MATCH(AE25, 屬性克制表!$A$2:$A$20, 0), MATCH($M$1, 屬性克制表!$B$1:$T$1, 0))) -> 146496 | AJ25: =_xlfn.XLOOKUP(AD25, 數據!B$2:B$50, 數據!M$2:M$50) -> 218 | AK25: 投擲猴 | AL25: =AB25/(INDEX(屬性克制表!$B$2:$T$20, MATCH($A$1, 屬性克制表!$A$2:$A$20, 0), MATCH(Z25, 屬性克制表!$B$1:$T$1, 0)) * INDEX(屬性克制表!$B$2:$T$20, MATCH($A$1, 屬性克制表!$A$2:$A$20, 0), MATCH(AA25, 屬性克制表!$B$1:$T$1, 0))) -> 24.104 | AM25: 投擲猴 | AN25: =AB25/(INDEX(屬性克制表!$B$2:$T$20, MATCH($C$1, 屬性克制表!$A$2:$A$20, 0), MATCH(Z25, 屬性克制表!$B$1:$T$1, 0)) * INDEX(屬性克制表!$B$2:$T$20, MATCH($C$1, 屬性克制表!$A$2:$A$20, 0), MATCH(AA25, 屬性克制表!$B$1:$T$1, 0))) -> 24.104 | AO25: 投擲猴 | AP25: =AB25/(INDEX(屬性克制表!$B$2:$T$20, MATCH($E$1, 屬性克制表!$A$2:$A$20, 0), MATCH(Z25, 屬性克制表!$B$1:$T$1, 0)) * INDEX(屬性克制表!$B$2:$T$20, MATCH($E$1, 屬性克制表!$A$2:$A$20, 0), MATCH(AA25, 屬性克制表!$B$1:$T$1, 0))) -> 24.104 | AQ25: 投擲猴 | AR25: =AB25/(INDEX(屬性克制表!$B$2:$T$20, MATCH($G$1, 屬性克制表!$A$2:$A$20, 0), MATCH(Z25, 屬性克制表!$B$1:$T$1, 0)) * INDEX(屬性克制表!$B$2:$T$20, MATCH($G$1, 屬性克制表!$A$2:$A$20, 0), MATCH(AA25, 屬性克制表!$B$1:$T$1, 0))) -> 24.104
A26: 鋼鎧鴉 | B26: 31.35 | C26: 水箭龜 | D26: 27.825 | E26: 巨鉗蟹 | F26: 31.0896 | G26: 急凍鳥 | H26: 30.504 | J26: 蒼響 | K26: 鋼 | L26: Y | M26: 291 | N26: D | O26: 122220 | P26: =O26/$O$3 -> 0.55995998 | Y26: 妙蛙花 | Z26: 草 | AA26: 毒 | AB26: =數據!P25 -> 23.712 | AC26: =數據!P24 -> 24.104 | AD26: 耿鬼 | AE26: 幽靈 | AF26: Y | AG26: =AJ26 -> 223 | AH26: D | AI26: =AG26*IF(AH26="G", 450, IF(AH26="D", 350, 0)) * IF(AF26="Y", 1.2, 1)*(INDEX(屬性克制表!$B$2:$T$20, MATCH(AE26, 屬性克制表!$A$2:$A$20, 0), MATCH($L$1, 屬性克制表!$B$1:$T$1, 0)) * INDEX(屬性克制表!$B$2:$T$20, MATCH(AE26, 屬性克制表!$A$2:$A$20, 0), MATCH($M$1, 屬性克制表!$B$1:$T$1, 0))) -> 93660 | AJ26: =_xlfn.XLOOKUP(AD26, 數據!B$2:B$50, 數據!M$2:M$50) -> 223 | AK26: 妙蛙花 | AL26: =AB26/(INDEX(屬性克制表!$B$2:$T$20, MATCH($A$1, 屬性克制表!$A$2:$A$20, 0), MATCH(Z26, 屬性克制表!$B$1:$T$1, 0)) * INDEX(屬性克制表!$B$2:$T$20, MATCH($A$1, 屬性克制表!$A$2:$A$20, 0), MATCH(AA26, 屬性克制表!$B$1:$T$1, 0))) -> 37.9392 | AM26: 妙蛙花 | AN26: =AB26/(INDEX(屬性克制表!$B$2:$T$20, MATCH($C$1, 屬性克制表!$A$2:$A$20, 0), MATCH(Z26, 屬性克制表!$B$1:$T$1, 0)) * INDEX(屬性克制表!$B$2:$T$20, MATCH($C$1, 屬性克制表!$A$2:$A$20, 0), MATCH(AA26, 屬性克制表!$B$1:$T$1, 0))) -> 23.712 | AO26: 妙蛙花 | AP26: =AB26/(INDEX(屬性克制表!$B$2:$T$20, MATCH($E$1, 屬性克制表!$A$2:$A$20, 0), MATCH(Z26, 屬性克制表!$B$1:$T$1, 0)) * INDEX(屬性克制表!$B$2:$T$20, MATCH($E$1, 屬性克制表!$A$2:$A$20, 0), MATCH(AA26, 屬性克制表!$B$1:$T$1, 0))) -> 37.9392 | AQ26: 妙蛙花 | AR26: =AB26/(INDEX(屬性克制表!$B$2:$T$20, MATCH($G$1, 屬性克制表!$A$2:$A$20, 0), MATCH(Z26, 屬性克制表!$B$1:$T$1, 0)) * INDEX(屬性克制表!$B$2:$T$20, MATCH($G$1, 屬性克制表!$A$2:$A$20, 0), MATCH(AA26, 屬性克制表!$B$1:$T$1, 0))) -> 37.9392
A27: 急凍鳥 | B27: 30.504 | C27: 拉帝歐斯 | D27: 27.808 | E27: 急凍鳥 | F27: 30.504 | G27: 戰弦蠑螈 | H27: 29.8144 | J27: 拉普拉斯 | K27: 冰 | L27: Y | M27: 141 | N27: G | O27: 121824 | P27: =O27/$O$3 -> 0.55814567 | Y27: 毛毛角羊 | Z27: 一般 | AA27: 無 | AB27: =數據!P26 -> 24.883 | AC27: =數據!P25 -> 23.712 | AD27: 巨金怪 | AE27: 超能力 | AF27: Y | AG27: =AJ27 -> 214 | AH27: D | AI27: =AG27*IF(AH27="G", 450, IF(AH27="D", 350, 0)) * IF(AF27="Y", 1.2, 1)*(INDEX(屬性克制表!$B$2:$T$20, MATCH(AE27, 屬性克制表!$A$2:$A$20, 0), MATCH($L$1, 屬性克制表!$B$1:$T$1, 0)) * INDEX(屬性克制表!$B$2:$T$20, MATCH(AE27, 屬性克制表!$A$2:$A$20, 0), MATCH($M$1, 屬性克制表!$B$1:$T$1, 0))) -> 143808 | AJ27: =_xlfn.XLOOKUP(AD27, 數據!B$2:B$50, 數據!M$2:M$50) -> 214 | AK27: 毛毛角羊 | AL27: =AB27/(INDEX(屬性克制表!$B$2:$T$20, MATCH($A$1, 屬性克制表!$A$2:$A$20, 0), MATCH(Z27, 屬性克制表!$B$1:$T$1, 0)) * INDEX(屬性克制表!$B$2:$T$20, MATCH($A$1, 屬性克制表!$A$2:$A$20, 0), MATCH(AA27, 屬性克制表!$B$1:$T$1, 0))) -> 15.551875 | AM27: 毛毛角羊 | AN27: =AB27/(INDEX(屬性克制表!$B$2:$T$20, MATCH($C$1, 屬性克制表!$A$2:$A$20, 0), MATCH(Z27, 屬性克制表!$B$1:$T$1, 0)) * INDEX(屬性克制表!$B$2:$T$20, MATCH($C$1, 屬性克制表!$A$2:$A$20, 0), MATCH(AA27, 屬性克制表!$B$1:$T$1, 0))) -> 24.883 | AO27: 毛毛角羊 | AP27: =AB27/(INDEX(屬性克制表!$B$2:$T$20, MATCH($E$1, 屬性克制表!$A$2:$A$20, 0), MATCH(Z27, 屬性克制表!$B$1:$T$1, 0)) * INDEX(屬性克制表!$B$2:$T$20, MATCH($E$1, 屬性克制表!$A$2:$A$20, 0), MATCH(AA27, 屬性克制表!$B$1:$T$1, 0))) -> 24.883 | AQ27: 毛毛角羊 | AR27: =AB27/(INDEX(屬性克制表!$B$2:$T$20, MATCH($G$1, 屬性克制表!$A$2:$A$20, 0), MATCH(Z27, 屬性克制表!$B$1:$T$1, 0)) * INDEX(屬性克制表!$B$2:$T$20, MATCH($G$1, 屬性克制表!$A$2:$A$20, 0), MATCH(AA27, 屬性克制表!$B$1:$T$1, 0))) -> 24.883
A28: 巨金怪 | B28: 30.429 | C28: 藏瑪然特 | D28: 26.91875 | E28: 巨金怪 | F28: 30.429 | G28: 藏飽栗鼠 | H28: 29.295 | J28: 耿鬼 | K28: 幽靈 | L28: Y | M28: 223 | N28: G | O28: 120420 | P28: =O28/$O$3 -> 0.55171314 | Y28: 多刺菊石獸 | Z28: 岩石 | AA28: 水 | AB28: =數據!P27 -> 25.456 | AC28: =數據!P26 -> 24.883 | AD28: 巨金怪 | AE28: 鋼 | AF28: Y | AG28: =AJ28 -> 214 | AH28: D | AI28: =AG28*IF(AH28="G", 450, IF(AH28="D", 350, 0)) * IF(AF28="Y", 1.2, 1)*(INDEX(屬性克制表!$B$2:$T$20, MATCH(AE28, 屬性克制表!$A$2:$A$20, 0), MATCH($L$1, 屬性克制表!$B$1:$T$1, 0)) * INDEX(屬性克制表!$B$2:$T$20, MATCH(AE28, 屬性克制表!$A$2:$A$20, 0), MATCH($M$1, 屬性克制表!$B$1:$T$1, 0))) -> 89880 | AJ28: =_xlfn.XLOOKUP(AD28, 數據!B$2:B$50, 數據!M$2:M$50) -> 214 | AK28: 多刺菊石獸 | AL28: =AB28/(INDEX(屬性克制表!$B$2:$T$20, MATCH($A$1, 屬性克制表!$A$2:$A$20, 0), MATCH(Z28, 屬性克制表!$B$1:$T$1, 0)) * INDEX(屬性克制表!$B$2:$T$20, MATCH($A$1, 屬性克制表!$A$2:$A$20, 0), MATCH(AA28, 屬性克制表!$B$1:$T$1, 0))) -> 15.91 | AM28: 多刺菊石獸 | AN28: =AB28/(INDEX(屬性克制表!$B$2:$T$20, MATCH($C$1, 屬性克制表!$A$2:$A$20, 0), MATCH(Z28, 屬性克制表!$B$1:$T$1, 0)) * INDEX(屬性克制表!$B$2:$T$20, MATCH($C$1, 屬性克制表!$A$2:$A$20, 0), MATCH(AA28, 屬性克制表!$B$1:$T$1, 0))) -> 15.91 | AO28: 多刺菊石獸 | AP28: =AB28/(INDEX(屬性克制表!$B$2:$T$20, MATCH($E$1, 屬性克制表!$A$2:$A$20, 0), MATCH(Z28, 屬性克制表!$B$1:$T$1, 0)) * INDEX(屬性克制表!$B$2:$T$20, MATCH($E$1, 屬性克制表!$A$2:$A$20, 0), MATCH(AA28, 屬性克制表!$B$1:$T$1, 0))) -> 25.456 | AQ28: 多刺菊石獸 | AR28: =AB28/(INDEX(屬性克制表!$B$2:$T$20, MATCH($G$1, 屬性克制表!$A$2:$A$20, 0), MATCH(Z28, 屬性克制表!$B$1:$T$1, 0)) * INDEX(屬性克制表!$B$2:$T$20, MATCH($G$1, 屬性克制表!$A$2:$A$20, 0), MATCH(AA28, 屬性克制表!$B$1:$T$1, 0))) -> 25.456
A29: 戰弦蠑螈 | B29: 29.8144 | C29: 幾何雪花 | D29: 26.296 | E29: 藏飽栗鼠 | F29: 29.295 | G29: 耿鬼 | H29: 29.1584 | J29: 炎帝 | K29: 火 | L29: Y | M29: 175 | N29: D | O29: 117600 | P29: =O29/$O$3 -> 0.5387931 | Y29: 壺壺 | Z29: 岩石 | AA29: 蟲 | AB29: =數據!P28 -> 33.66 | AC29: =數據!P27 -> 25.456 | AD29: 龍頭地鼠 | AE29: 地面 | AF29: Y | AG29: =AJ29 -> 217 | AH29: D | AI29: =AG29*IF(AH29="G", 450, IF(AH29="D", 350, 0)) * IF(AF29="Y", 1.2, 1)*(INDEX(屬性克制表!$B$2:$T$20, MATCH(AE29, 屬性克制表!$A$2:$A$20, 0), MATCH($L$1, 屬性克制表!$B$1:$T$1, 0)) * INDEX(屬性克制表!$B$2:$T$20, MATCH(AE29, 屬性克制表!$A$2:$A$20, 0), MATCH($M$1, 屬性克制表!$B$1:$T$1, 0))) -> 56962.5 | AJ29: =_xlfn.XLOOKUP(AD29, 數據!B$2:B$50, 數據!M$2:M$50) -> 217 | AK29: 壺壺 | AL29: =AB29/(INDEX(屬性克制表!$B$2:$T$20, MATCH($A$1, 屬性克制表!$A$2:$A$20, 0), MATCH(Z29, 屬性克制表!$B$1:$T$1, 0)) * INDEX(屬性克制表!$B$2:$T$20, MATCH($A$1, 屬性克制表!$A$2:$A$20, 0), MATCH(AA29, 屬性克制表!$B$1:$T$1, 0))) -> 33.66 | AM29: 壺壺 | AN29: =AB29/(INDEX(屬性克制表!$B$2:$T$20, MATCH($C$1, 屬性克制表!$A$2:$A$20, 0), MATCH(Z29, 屬性克制表!$B$1:$T$1, 0)) * INDEX(屬性克制表!$B$2:$T$20, MATCH($C$1, 屬性克制表!$A$2:$A$20, 0), MATCH(AA29, 屬性克制表!$B$1:$T$1, 0))) -> 33.66 | AO29: 壺壺 | AP29: =AB29/(INDEX(屬性克制表!$B$2:$T$20, MATCH($E$1, 屬性克制表!$A$2:$A$20, 0), MATCH(Z29, 屬性克制表!$B$1:$T$1, 0)) * INDEX(屬性克制表!$B$2:$T$20, MATCH($E$1, 屬性克制表!$A$2:$A$20, 0), MATCH(AA29, 屬性克制表!$B$1:$T$1, 0))) -> 21.0375 | AQ29: 壺壺 | AR29: =AB29/(INDEX(屬性克制表!$B$2:$T$20, MATCH($G$1, 屬性克制表!$A$2:$A$20, 0), MATCH(Z29, 屬性克制表!$B$1:$T$1, 0)) * INDEX(屬性克制表!$B$2:$T$20, MATCH($G$1, 屬性克制表!$A$2:$A$20, 0), MATCH(AA29, 屬性克制表!$B$1:$T$1, 0))) -> 33.66
A30: 胡地 | B30: 29.2608 | C30: 怪力 | D30: 25.38 | E30: 千面避役 | F30: 28.9296 | G30: 武道熊師(連) | H30: 28.2 | J30: 洛奇亞 | K30: 超能力 | L30: Y | M30: 164 | N30: D | O30: 110208 | P30: =O30/$O$3 -> 0.50492611 | Y30: 怪力 | Z30: 格鬥 | AA30: 無 | AB30: =數據!P29 -> 25.38 | AC30: =數據!P28 -> 33.66 | AD30: 龍頭地鼠 | AE30: 鋼 | AF30: Y | AG30: =AJ30 -> 217 | AH30: D | AI30: =AG30*IF(AH30="G", 450, IF(AH30="D", 350, 0)) * IF(AF30="Y", 1.2, 1)*(INDEX(屬性克制表!$B$2:$T$20, MATCH(AE30, 屬性克制表!$A$2:$A$20, 0), MATCH($L$1, 屬性克制表!$B$1:$T$1, 0)) * INDEX(屬性克制表!$B$2:$T$20, MATCH(AE30, 屬性克制表!$A$2:$A$20, 0), MATCH($M$1, 屬性克制表!$B$1:$T$1, 0))) -> 91140 | AJ30: =_xlfn.XLOOKUP(AD30, 數據!B$2:B$50, 數據!M$2:M$50) -> 217 | AK30: 怪力 | AL30: =AB30/(INDEX(屬性克制表!$B$2:$T$20, MATCH($A$1, 屬性克制表!$A$2:$A$20, 0), MATCH(Z30, 屬性克制表!$B$1:$T$1, 0)) * INDEX(屬性克制表!$B$2:$T$20, MATCH($A$1, 屬性克制表!$A$2:$A$20, 0), MATCH(AA30, 屬性克制表!$B$1:$T$1, 0))) -> 25.38 | AM30: 怪力 | AN30: =AB30/(INDEX(屬性克制表!$B$2:$T$20, MATCH($C$1, 屬性克制表!$A$2:$A$20, 0), MATCH(Z30, 屬性克制表!$B$1:$T$1, 0)) * INDEX(屬性克制表!$B$2:$T$20, MATCH($C$1, 屬性克制表!$A$2:$A$20, 0), MATCH(AA30, 屬性克制表!$B$1:$T$1, 0))) -> 25.38 | AO30: 怪力 | AP30: =AB30/(INDEX(屬性克制表!$B$2:$T$20, MATCH($E$1, 屬性克制表!$A$2:$A$20, 0), MATCH(Z30, 屬性克制表!$B$1:$T$1, 0)) * INDEX(屬性克制表!$B$2:$T$20, MATCH($E$1, 屬性克制表!$A$2:$A$20, 0), MATCH(AA30, 屬性克制表!$B$1:$T$1, 0))) -> 25.38 | AQ30: 怪力 | AR30: =AB30/(INDEX(屬性克制表!$B$2:$T$20, MATCH($G$1, 屬性克制表!$A$2:$A$20, 0), MATCH(Z30, 屬性克制表!$B$1:$T$1, 0)) * INDEX(屬性克制表!$B$2:$T$20, MATCH($G$1, 屬性克制表!$A$2:$A$20, 0), MATCH(AA30, 屬性克制表!$B$1:$T$1, 0))) -> 25.38
A31: 武道熊師(連) | B31: 28.2 | C31: 毛毛角羊 | D31: 24.883 | E31: 武道熊師(一) | F31: 28.2 | G31: 水箭龜 | H31: 27.825 | J31: 怪力 | K31: 格鬥 | L31: Y | M31: 201 | N31: G | O31: 108540 | P31: =O31/$O$3 -> 0.49728404 | Y31: 噴火龍 | Z31: 火 | AA31: 飛行 | AB31: =數據!P30 -> 22.62 | AC31: =數據!P29 -> 25.38 | AD31: 武道熊師(一) | AE31: 惡 | AF31: Y | AG31: =AJ31 -> 210 | AH31: D | AI31: =AG31*IF(AH31="G", 450, IF(AH31="D", 350, 0)) * IF(AF31="Y", 1.2, 1)*(INDEX(屬性克制表!$B$2:$T$20, MATCH(AE31, 屬性克制表!$A$2:$A$20, 0), MATCH($L$1, 屬性克制表!$B$1:$T$1, 0)) * INDEX(屬性克制表!$B$2:$T$20, MATCH(AE31, 屬性克制表!$A$2:$A$20, 0), MATCH($M$1, 屬性克制表!$B$1:$T$1, 0))) -> 55125 | AJ31: =_xlfn.XLOOKUP(AD31, 數據!B$2:B$50, 數據!M$2:M$50) -> 210 | AK31: 噴火龍 | AL31: =AB31/(INDEX(屬性克制表!$B$2:$T$20, MATCH($A$1, 屬性克制表!$A$2:$A$20, 0), MATCH(Z31, 屬性克制表!$B$1:$T$1, 0)) * INDEX(屬性克制表!$B$2:$T$20, MATCH($A$1, 屬性克制表!$A$2:$A$20, 0), MATCH(AA31, 屬性克制表!$B$1:$T$1, 0))) -> 36.192 | AM31: 噴火龍 | AN31: =AB31/(INDEX(屬性克制表!$B$2:$T$20, MATCH($C$1, 屬性克制表!$A$2:$A$20, 0), MATCH(Z31, 屬性克制表!$B$1:$T$1, 0)) * INDEX(屬性克制表!$B$2:$T$20, MATCH($C$1, 屬性克制表!$A$2:$A$20, 0), MATCH(AA31, 屬性克制表!$B$1:$T$1, 0))) -> 36.157289 | AO31: 噴火龍 | AP31: =AB31/(INDEX(屬性克制表!$B$2:$T$20, MATCH($E$1, 屬性克制表!$A$2:$A$20, 0), MATCH(Z31, 屬性克制表!$B$1:$T$1, 0)) * INDEX(屬性克制表!$B$2:$T$20, MATCH($E$1, 屬性克制表!$A$2:$A$20, 0), MATCH(AA31, 屬性克制表!$B$1:$T$1, 0))) -> 14.1375 | AQ31: 噴火龍 | AR31: =AB31/(INDEX(屬性克制表!$B$2:$T$20, MATCH($G$1, 屬性克制表!$A$2:$A$20, 0), MATCH(Z31, 屬性克制表!$B$1:$T$1, 0)) * INDEX(屬性克制表!$B$2:$T$20, MATCH($G$1, 屬性克制表!$A$2:$A$20, 0), MATCH(AA31, 屬性克制表!$B$1:$T$1, 0))) -> 36.192
... A46: 雷伊布 | B46: 21.84 | C46: 巨鉗蟹 | D46: 19.431 | E46: 壺壺 | F46: 21.0375 | G46: 月亮伊布 | H46: 22.9775 | J46: 沙奈朵 | K46: 妖精 | L46: Y | M46: 199 | N46: D | O46: 83580 | P46: =O46/$O$3 -> 0.38292796 | Y46: 勾魂眼 | Z46: 幽靈 | AA46: 惡 | AB46: =數據!P45 -> 13.688 | AC46: =數據!P44 -> 15.827 | AD46: 噴火龍 | AE46: 飛行 | AF46: Y | AG46: =AJ46 -> 187 | AH46: D | AI46: =AG46*IF(AH46="G", 450, IF(AH46="D", 350, 0)) * IF(AF46="Y", 1.2, 1)*(INDEX(屬性克制表!$B$2:$T$20, MATCH(AE46, 屬性克制表!$A$2:$A$20, 0), MATCH($L$1, 屬性克制表!$B$1:$T$1, 0)) * INDEX(屬性克制表!$B$2:$T$20, MATCH(AE46, 屬性克制表!$A$2:$A$20, 0), MATCH($M$1, 屬性克制表!$B$1:$T$1, 0))) -> 201062.4 | AJ46: =_xlfn.XLOOKUP(AD46, 數據!B$2:B$50, 數據!M$2:M$50) -> 187 | AK46: 勾魂眼 | AL46: =AB46/(INDEX(屬性克制表!$B$2:$T$20, MATCH($A$1, 屬性克制表!$A$2:$A$20, 0), MATCH(Z46, 屬性克制表!$B$1:$T$1, 0)) * INDEX(屬性克制表!$B$2:$T$20, MATCH($A$1, 屬性克制表!$A$2:$A$20, 0), MATCH(AA46, 屬性克制表!$B$1:$T$1, 0))) -> 21.879795 | AM46: 勾魂眼 | AN46: =AB46/(INDEX(屬性克制表!$B$2:$T$20, MATCH($C$1, 屬性克制表!$A$2:$A$20, 0), MATCH(Z46, 屬性克制表!$B$1:$T$1, 0)) * INDEX(屬性克制表!$B$2:$T$20, MATCH($C$1, 屬性克制表!$A$2:$A$20, 0), MATCH(AA46, 屬性克制表!$B$1:$T$1, 0))) -> 13.688 | AO46: 勾魂眼 | AP46: =AB46/(INDEX(屬性克制表!$B$2:$T$20, MATCH($E$1, 屬性克制表!$A$2:$A$20, 0), MATCH(Z46, 屬性克制表!$B$1:$T$1, 0)) * INDEX(屬性克制表!$B$2:$T$20, MATCH($E$1, 屬性克制表!$A$2:$A$20, 0), MATCH(AA46, 屬性克制表!$B$1:$T$1, 0))) -> 13.688 | AQ46: 勾魂眼 | AR46: =AB46/(INDEX(屬性克制表!$B$2:$T$20, MATCH($G$1, 屬性克制表!$A$2:$A$20, 0), MATCH(Z46, 屬性克制表!$B$1:$T$1, 0)) * INDEX(屬性克制表!$B$2:$T$20, MATCH($G$1, 屬性克制表!$A$2:$A$20, 0), MATCH(AA46, 屬性克制表!$B$1:$T$1, 0))) -> 8.555
A47: 火伊布 | B47: 21.42 | C47: 巨金怪 | D47: 19.018125 | E47: 太陽伊布 | F47: 21 | G47: 吼鯨王 | H47: 22.88 | J47: 艾路雷朵 | K47: 格鬥 | L47: Y | M47: 199 | N47: D | O47: 83580 | P47: =O47/$O$3 -> 0.38292796 | Y47: =數據!B46 -> 胡地 | Z47: =數據!C46 -> 超能力 | AA47: =數據!D46 -> 無 | AB47: =數據!P46 -> 18.288 | AC47: =數據!P45 -> 13.688 | AD47: 噴火龍 | AE47: 火 | AF47: Y | AG47: =AJ47 -> 187 | AH47: D | AI47: =AG47*IF(AH47="G", 450, IF(AH47="D", 350, 0)) * IF(AF47="Y", 1.2, 1)*(INDEX(屬性克制表!$B$2:$T$20, MATCH(AE47, 屬性克制表!$A$2:$A$20, 0), MATCH($L$1, 屬性克制表!$B$1:$T$1, 0)) * INDEX(屬性克制表!$B$2:$T$20, MATCH(AE47, 屬性克制表!$A$2:$A$20, 0), MATCH($M$1, 屬性克制表!$B$1:$T$1, 0))) -> 125664 | AJ47: =_xlfn.XLOOKUP(AD47, 數據!B$2:B$50, 數據!M$2:M$50) -> 187 | AK47: =Y47 -> 胡地 | AL47: =AB47/(INDEX(屬性克制表!$B$2:$T$20, MATCH($A$1, 屬性克制表!$A$2:$A$20, 0), MATCH(Z47, 屬性克制表!$B$1:$T$1, 0)) * INDEX(屬性克制表!$B$2:$T$20, MATCH($A$1, 屬性克制表!$A$2:$A$20, 0), MATCH(AA47, 屬性克制表!$B$1:$T$1, 0))) -> 29.2608 | AM47: =Y47 -> 胡地 | AN47: =AB47/(INDEX(屬性克制表!$B$2:$T$20, MATCH($C$1, 屬性克制表!$A$2:$A$20, 0), MATCH(Z47, 屬性克制表!$B$1:$T$1, 0)) * INDEX(屬性克制表!$B$2:$T$20, MATCH($C$1, 屬性克制表!$A$2:$A$20, 0), MATCH(AA47, 屬性克制表!$B$1:$T$1, 0))) -> 18.288 | AO47: =Y47 -> 胡地 | AP47: =AB47/(INDEX(屬性克制表!$B$2:$T$20, MATCH($E$1, 屬性克制表!$A$2:$A$20, 0), MATCH(Z47, 屬性克制表!$B$1:$T$1, 0)) * INDEX(屬性克制表!$B$2:$T$20, MATCH($E$1, 屬性克制表!$A$2:$A$20, 0), MATCH(AA47, 屬性克制表!$B$1:$T$1, 0))) -> 18.288 | AQ47: =Y47 -> 胡地 | AR47: =AB47/(INDEX(屬性克制表!$B$2:$T$20, MATCH($G$1, 屬性克制表!$A$2:$A$20, 0), MATCH(Z47, 屬性克制表!$B$1:$T$1, 0)) * INDEX(屬性克制表!$B$2:$T$20, MATCH($G$1, 屬性克制表!$A$2:$A$20, 0), MATCH(AA47, 屬性克制表!$B$1:$T$1, 0))) -> 18.288
A48: 鐮刀盔 | B48: 21.172 | C48: 胡地 | D48: 18.288 | E48: 高傲雉雞 | F48: 20.32 | G48: 雷伊布 | H48: 21.84 | J48: 布莉姆溫 | K48: 妖精 | L48: Y | M48: 198 | N48: D | O48: 83160 | P48: =O48/$O$3 -> 0.38100369 | Y48: =數據!B47 -> 鋁鋼龍 | Z48: =數據!C47 -> 鋼 | AA48: =數據!D47 -> 龍 | AB48: =數據!P47 -> 23.226 | AD48: 耿鬼 | AE48: 惡 | AF48: N | AG48: =AJ48 -> 223 | AH48: D | AI48: =AG48*IF(AH48="G", 450, IF(AH48="D", 350, 0)) * IF(AF48="Y", 1.2, 1)*(INDEX(屬性克制表!$B$2:$T$20, MATCH(AE48, 屬性克制表!$A$2:$A$20, 0), MATCH($L$1, 屬性克制表!$B$1:$T$1, 0)) * INDEX(屬性克制表!$B$2:$T$20, MATCH(AE48, 屬性克制表!$A$2:$A$20, 0), MATCH($M$1, 屬性克制表!$B$1:$T$1, 0))) -> 48781.25 | AJ48: =_xlfn.XLOOKUP(AD48, 數據!B$2:B$50, 數據!M$2:M$50) -> 223 | AK48: =Y48 -> 鋁鋼龍 | AL48: =AB48/(INDEX(屬性克制表!$B$2:$T$20, MATCH($A$1, 屬性克制表!$A$2:$A$20, 0), MATCH(Z48, 屬性克制表!$B$1:$T$1, 0)) * INDEX(屬性克制表!$B$2:$T$20, MATCH($A$1, 屬性克制表!$A$2:$A$20, 0), MATCH(AA48, 屬性克制表!$B$1:$T$1, 0))) -> 14.51625 | AM48: =Y48 -> 鋁鋼龍 | AN48: =AB48/(INDEX(屬性克制表!$B$2:$T$20, MATCH($C$1, 屬性克制表!$A$2:$A$20, 0), MATCH(Z48, 屬性克制表!$B$1:$T$1, 0)) * INDEX(屬性克制表!$B$2:$T$20, MATCH($C$1, 屬性克制表!$A$2:$A$20, 0), MATCH(AA48, 屬性克制表!$B$1:$T$1, 0))) -> 14.51625 | AO48: =Y48 -> 鋁鋼龍 | AP48: =AB48/(INDEX(屬性克制表!$B$2:$T$20, MATCH($E$1, 屬性克制表!$A$2:$A$20, 0), MATCH(Z48, 屬性克制表!$B$1:$T$1, 0)) * INDEX(屬性克制表!$B$2:$T$20, MATCH($E$1, 屬性克制表!$A$2:$A$20, 0), MATCH(AA48, 屬性克制表!$B$1:$T$1, 0))) -> 37.1616 | AQ48: =Y48 -> 鋁鋼龍 | AR48: =AB48/(INDEX(屬性克制表!$B$2:$T$20, MATCH($G$1, 屬性克制表!$A$2:$A$20, 0), MATCH(Z48, 屬性克制表!$B$1:$T$1, 0)) * INDEX(屬性克制表!$B$2:$T$20, MATCH($G$1, 屬性克制表!$A$2:$A$20, 0), MATCH(AA48, 屬性克制表!$B$1:$T$1, 0))) -> 23.226
A49: 拉普拉斯 | B49: 21.13125 | C49: 千面避役 | D49: 18.081 | E49: 布莉姆溫 | F49: 19.84 | G49: 鐮刀盔 | H49: 21.172 | J49: 吼鯨王 | K49: 超能力 | L49: N | M49: 147 | N49: D | O49: 82320 | P49: =O49/$O$3 -> 0.37715517 | Y49: =數據!B48 -> 甜冷美后 | Z49: =數據!C48 -> 草 | AA49: 無 | AB49: =數據!P48 -> 24.9 | AD49: 巴大蝶 | AE49: 蟲 | AF49: Y | AG49: =AJ49 -> 143 | AH49: G | AI49: =AG49*IF(AH49="G", 450, IF(AH49="D", 350, 0)) * IF(AF49="Y", 1.2, 1)*(INDEX(屬性克制表!$B$2:$T$20, MATCH(AE49, 屬性克制表!$A$2:$A$20, 0), MATCH($L$1, 屬性克制表!$B$1:$T$1, 0)) * INDEX(屬性克制表!$B$2:$T$20, MATCH(AE49, 屬性克制表!$A$2:$A$20, 0), MATCH($M$1, 屬性克制表!$B$1:$T$1, 0))) -> 77220 | AJ49: =_xlfn.XLOOKUP(AD49, 數據!B$2:B$50, 數據!M$2:M$50) -> 143 | AK49: =Y49 -> 甜冷美后 | AL49: =AB49/(INDEX(屬性克制表!$B$2:$T$20, MATCH($A$1, 屬性克制表!$A$2:$A$20, 0), MATCH(Z49, 屬性克制表!$B$1:$T$1, 0)) * INDEX(屬性克制表!$B$2:$T$20, MATCH($A$1, 屬性克制表!$A$2:$A$20, 0), MATCH(AA49, 屬性克制表!$B$1:$T$1, 0))) -> 24.9 | AM49: =Y49 -> 甜冷美后 | AN49: =AB49/(INDEX(屬性克制表!$B$2:$T$20, MATCH($C$1, 屬性克制表!$A$2:$A$20, 0), MATCH(Z49, 屬性克制表!$B$1:$T$1, 0)) * INDEX(屬性克制表!$B$2:$T$20, MATCH($C$1, 屬性克制表!$A$2:$A$20, 0), MATCH(AA49, 屬性克制表!$B$1:$T$1, 0))) -> 39.84 | AO49: =Y49 -> 甜冷美后 | AP49: =AB49/(INDEX(屬性克制表!$B$2:$T$20, MATCH($E$1, 屬性克制表!$A$2:$A$20, 0), MATCH(Z49, 屬性克制表!$B$1:$T$1, 0)) * INDEX(屬性克制表!$B$2:$T$20, MATCH($E$1, 屬性克制表!$A$2:$A$20, 0), MATCH(AA49, 屬性克制表!$B$1:$T$1, 0))) -> 39.84 | AQ49: =Y49 -> 甜冷美后 | AR49: =AB49/(INDEX(屬性克制表!$B$2:$T$20, MATCH($G$1, 屬性克制表!$A$2:$A$20, 0), MATCH(Z49, 屬性克制表!$B$1:$T$1, 0)) * INDEX(屬性克制表!$B$2:$T$20, MATCH($G$1, 屬性克制表!$A$2:$A$20, 0), MATCH(AA49, 屬性克制表!$B$1:$T$1, 0))) -> 24.9
A50: 卡比獸 | B50: 21.105 | C50: 雷公 | D50: 17.10625 | E50: 列陣兵 | F50: 19.591 | G50: 太陽伊布 | H50: 21 | J50: 巴大蝶 | K50: 超能力 | L50: N | M50: 143 | N50: D | O50: 80080 | P50: =O50/$O$3 -> 0.36689245 | Y50: =數據!B49 -> 沙奈朵 | Z50: =數據!C49 -> 超能力 | AA50: =數據!D49 -> 妖精 | AB50: =數據!P49 -> 24.07 | AD50: 巨金怪 | AE50: 蟲 | AF50: N | AG50: =AJ50 -> 214 | AH50: D | AI50: =AG50*IF(AH50="G", 450, IF(AH50="D", 350, 0)) * IF(AF50="Y", 1.2, 1)*(INDEX(屬性克制表!$B$2:$T$20, MATCH(AE50, 屬性克制表!$A$2:$A$20, 0), MATCH($L$1, 屬性克制表!$B$1:$T$1, 0)) * INDEX(屬性克制表!$B$2:$T$20, MATCH(AE50, 屬性克制表!$A$2:$A$20, 0), MATCH($M$1, 屬性克制表!$B$1:$T$1, 0))) -> 74900 | AJ50: =_xlfn.XLOOKUP(AD50, 數據!B$2:B$50, 數據!M$2:M$50) -> 214 | AK50: =Y50 -> 沙奈朵 | AL50: =AB50/(INDEX(屬性克制表!$B$2:$T$20, MATCH($A$1, 屬性克制表!$A$2:$A$20, 0), MATCH(Z50, 屬性克制表!$B$1:$T$1, 0)) * INDEX(屬性克制表!$B$2:$T$20, MATCH($A$1, 屬性克制表!$A$2:$A$20, 0), MATCH(AA50, 屬性克制表!$B$1:$T$1, 0))) -> 61.6192 | AM50: =Y50 -> 沙奈朵 | AN50: =AB50/(INDEX(屬性克制表!$B$2:$T$20, MATCH($C$1, 屬性克制表!$A$2:$A$20, 0), MATCH(Z50, 屬性克制表!$B$1:$T$1, 0)) * INDEX(屬性克制表!$B$2:$T$20, MATCH($C$1, 屬性克制表!$A$2:$A$20, 0), MATCH(AA50, 屬性克制表!$B$1:$T$1, 0))) -> 24.07 | AO50: =Y50 -> 沙奈朵 | AP50: =AB50/(INDEX(屬性克制表!$B$2:$T$20, MATCH($E$1, 屬性克制表!$A$2:$A$20, 0), MATCH(Z50, 屬性克制表!$B$1:$T$1, 0)) * INDEX(屬性克制表!$B$2:$T$20, MATCH($E$1, 屬性克制表!$A$2:$A$20, 0), MATCH(AA50, 屬性克制表!$B$1:$T$1, 0))) -> 24.07 | AQ50: =Y50 -> 沙奈朵 | AR50: =AB50/(INDEX(屬性克制表!$B$2:$T$20, MATCH($G$1, 屬性克制表!$A$2:$A$20, 0), MATCH(Z50, 屬性克制表!$B$1:$T$1, 0)) * INDEX(屬性克制表!$B$2:$T$20, MATCH($G$1, 屬性克制表!$A$2:$A$20, 0), MATCH(AA50, 屬性克制表!$B$1:$T$1, 0))) -> 24.07
A51: 高傲雉雞 | B51: 20.32 | C51: 多刺菊石獸 | D51: 15.91 | E51: 戰弦蠑螈 | F51: 18.634 | G51: 高傲雉雞 | H51: 20.32 | J51: 胡地 | K51: 格鬥 | L51: N | M51: 225 | N51: D | O51: 78750 | P51: =O51/$O$3 -> 0.36079895 | Y51: =數據!B50 -> 超級巨伊布 | Z51: =數據!C50 -> 一般 | AA51: =數據!D50 -> 無 | AB51: =數據!P50 -> 12.954 | AD51: 藏飽栗鼠 | AE51: 草 | AF51: N | AG51: =AJ51 -> 138 | AH51: D | AI51: =AG51*IF(AH51="G", 450, IF(AH51="D", 350, 0)) * IF(AF51="Y", 1.2, 1)*(INDEX(屬性克制表!$B$2:$T$20, MATCH(AE51, 屬性克制表!$A$2:$A$20, 0), MATCH($L$1, 屬性克制表!$B$1:$T$1, 0)) * INDEX(屬性克制表!$B$2:$T$20, MATCH(AE51, 屬性克制表!$A$2:$A$20, 0), MATCH($M$1, 屬性克制表!$B$1:$T$1, 0))) -> 30187.5 | AJ51: =_xlfn.XLOOKUP(AD51, 數據!B$2:B$50, 數據!M$2:M$50) -> 138 | AK51: =Y51 -> 超級巨伊布 | AL51: =AB51/(INDEX(屬性克制表!$B$2:$T$20, MATCH($A$1, 屬性克制表!$A$2:$A$20, 0), MATCH(Z51, 屬性克制表!$B$1:$T$1, 0)) * INDEX(屬性克制表!$B$2:$T$20, MATCH($A$1, 屬性克制表!$A$2:$A$20, 0), MATCH(AA51, 屬性克制表!$B$1:$T$1, 0))) -> 8.09625 | AM51: =Y51 -> 超級巨伊布 | AN51: =AB51/(INDEX(屬性克制表!$B$2:$T$20, MATCH($C$1, 屬性克制表!$A$2:$A$20, 0), MATCH(Z51, 屬性克制表!$B$1:$T$1, 0)) * INDEX(屬性克制表!$B$2:$T$20, MATCH($C$1, 屬性克制表!$A$2:$A$20, 0), MATCH(AA51, 屬性克制表!$B$1:$T$1, 0))) -> 12.954 | AO51: =Y51 -> 超級巨伊布 | AP51: =AB51/(INDEX(屬性克制表!$B$2:$T$20, MATCH($E$1, 屬性克制表!$A$2:$A$20, 0), MATCH(Z51, 屬性克制表!$B$1:$T$1, 0)) * INDEX(屬性克制表!$B$2:$T$20, MATCH($E$1, 屬性克制表!$A$2:$A$20, 0), MATCH(AA51, 屬性克制表!$B$1:$T$1, 0))) -> 12.954 | AQ51: =Y51 -> 超級巨伊布 | AR51: =AB51/(INDEX(屬性克制表!$B$2:$T$20, MATCH($G$1, 屬性克制表!$A$2:$A$20, 0), MATCH(Z51, 屬性克制表!$B$1:$T$1, 0)) * INDEX(屬性克制表!$B$2:$T$20, MATCH($G$1, 屬性克制表!$A$2:$A$20, 0), MATCH(AA51, 屬性克制表!$B$1:$T$1, 0))) -> 12.954
A52: 列陣兵 | B52: 19.591 | C52: 閃焰王牌 | D52: 15.225 | E52: 胡地 | F52: 18.288 | G52: 布莉姆溫 | H52: 19.84 | J52: 巴大蝶 | K52: 蟲 | L52: Y | M52: 143 | N52: G | O52: 77220 | P52: =O52/$O$3 -> 0.35378914 | Y52: =數據!B51 -> 水伊布 | Z52: =數據!C51 -> 水 | AA52: =數據!D51 -> 無 | AB52: =數據!P51 -> 31.97 | AD52: 毛毛角羊 | AE52: 格鬥 | AF52: N | AG52: =AJ52 -> 136 | AH52: D | AI52: =AG52*IF(AH52="G", 450, IF(AH52="D", 350, 0)) * IF(AF52="Y", 1.2, 1)*(INDEX(屬性克制表!$B$2:$T$20, MATCH(AE52, 屬性克制表!$A$2:$A$20, 0), MATCH($L$1, 屬性克制表!$B$1:$T$1, 0)) * INDEX(屬性克制表!$B$2:$T$20, MATCH(AE52, 屬性克制表!$A$2:$A$20, 0), MATCH($M$1, 屬性克制表!$B$1:$T$1, 0))) -> 47600 | AJ52: =_xlfn.XLOOKUP(AD52, 數據!B$2:B$50, 數據!M$2:M$50) -> 136 | AK52: =Y52 -> 水伊布 | AL52: =AB52/(INDEX(屬性克制表!$B$2:$T$20, MATCH($A$1, 屬性克制表!$A$2:$A$20, 0), MATCH(Z52, 屬性克制表!$B$1:$T$1, 0)) * INDEX(屬性克制表!$B$2:$T$20, MATCH($A$1, 屬性克制表!$A$2:$A$20, 0), MATCH(AA52, 屬性克制表!$B$1:$T$1, 0))) -> 31.97 | AM52: =Y52 -> 水伊布 | AN52: =AB52/(INDEX(屬性克制表!$B$2:$T$20, MATCH($C$1, 屬性克制表!$A$2:$A$20, 0), MATCH(Z52, 屬性克制表!$B$1:$T$1, 0)) * INDEX(屬性克制表!$B$2:$T$20, MATCH($C$1, 屬性克制表!$A$2:$A$20, 0), MATCH(AA52, 屬性克制表!$B$1:$T$1, 0))) -> 31.97 | AO52: =Y52 -> 水伊布 | AP52: =AB52/(INDEX(屬性克制表!$B$2:$T$20, MATCH($E$1, 屬性克制表!$A$2:$A$20, 0), MATCH(Z52, 屬性克制表!$B$1:$T$1, 0)) * INDEX(屬性克制表!$B$2:$T$20, MATCH($E$1, 屬性克制表!$A$2:$A$20, 0), MATCH(AA52, 屬性克制表!$B$1:$T$1, 0))) -> 51.152 | AQ52: =Y52 -> 水伊布 | AR52: =AB52/(INDEX(屬性克制表!$B$2:$T$20, MATCH($G$1, 屬性克制表!$A$2:$A$20, 0), MATCH(Z52, 屬性克制表!$B$1:$T$1, 0)) * INDEX(屬性克制表!$B$2:$T$20, MATCH($G$1, 屬性克制表!$A$2:$A$20, 0), MATCH(AA52, 屬性克制表!$B$1:$T$1, 0))) -> 31.97
A53: 巨鉗蟹 | B53: 19.431 | C53: 龍頭地鼠 | D53: 14.80625 | E53: 耿鬼 | F53: 18.224 | G53: 列陣兵 | H53: 19.591 | J53: 投擲猴 | K53: 格鬥 | L53: Y | M53: 181 | N53: D | O53: 76020 | P53: =O53/$O$3 -> 0.34829126 | Y53: =數據!B52 -> 雷伊布 | Z53: =數據!C52 -> 電 | AA53: =數據!D52 -> 無 | AB53: =數據!P52 -> 21.84 | AD53: 千面避役 | AE53: 水 | AF53: Y | AG53: =AJ53 -> 217 | AH53: G | AI53: =AG53*IF(AH53="G", 450, IF(AH53="D", 350, 0)) * IF(AF53="Y", 1.2, 1)*(INDEX(屬性克制表!$B$2:$T$20, MATCH(AE53, 屬性克制表!$A$2:$A$20, 0), MATCH($L$1, 屬性克制表!$B$1:$T$1, 0)) * INDEX(屬性克制表!$B$2:$T$20, MATCH(AE53, 屬性克制表!$A$2:$A$20, 0), MATCH($M$1, 屬性克制表!$B$1:$T$1, 0))) -> 73237.5 | AJ53: =_xlfn.XLOOKUP(AD53, 數據!B$2:B$50, 數據!M$2:M$50) -> 217 | AK53: =Y53 -> 雷伊布 | AL53: =AB53/(INDEX(屬性克制表!$B$2:$T$20, MATCH($A$1, 屬性克制表!$A$2:$A$20, 0), MATCH(Z53, 屬性克制表!$B$1:$T$1, 0)) * INDEX(屬性克制表!$B$2:$T$20, MATCH($A$1, 屬性克制表!$A$2:$A$20, 0), MATCH(AA53, 屬性克制表!$B$1:$T$1, 0))) -> 21.84 | AM53: =Y53 -> 雷伊布 | AN53: =AB53/(INDEX(屬性克制表!$B$2:$T$20, MATCH($C$1, 屬性克制表!$A$2:$A$20, 0), MATCH(Z53, 屬性克制表!$B$1:$T$1, 0)) * INDEX(屬性克制表!$B$2:$T$20, MATCH($C$1, 屬性克制表!$A$2:$A$20, 0), MATCH(AA53, 屬性克制表!$B$1:$T$1, 0))) -> 13.65 | AO53: =Y53 -> 雷伊布 | AP53: =AB53/(INDEX(屬性克制表!$B$2:$T$20, MATCH($E$1, 屬性克制表!$A$2:$A$20, 0), MATCH(Z53, 屬性克制表!$B$1:$T$1, 0)) * INDEX(屬性克制表!$B$2:$T$20, MATCH($E$1, 屬性克制表!$A$2:$A$20, 0), MATCH(AA53, 屬性克制表!$B$1:$T$1, 0))) -> 21.84 | AQ53: =Y53 -> 雷伊布 | AR53: =AB53/(INDEX(屬性克制表!$B$2:$T$20, MATCH($G$1, 屬性克制表!$A$2:$A$20, 0), MATCH(Z53, 屬性克制表!$B$1:$T$1, 0)) * INDEX(屬性克制表!$B$2:$T$20, MATCH($G$1, 屬性克制表!$A$2:$A$20, 0), MATCH(AA53, 屬性克制表!$B$1:$T$1, 0))) -> 21.84
A54: 狒狒達摩 | B54: 19.3 | C54: 炎帝 | D54: 14.72 | E54: 巴大蝶 | F54: 15.827 | G54: 巨鉗蟹 | H54: 19.431 | J54: 巨金怪 | K54: 蟲 | L54: N | M54: 214 | N54: D | O54: 74900 | P54: =O54/$O$3 -> 0.34315989 | Y54: =數據!B53 -> 火伊布 | Z54: =數據!C53 -> 火 | AA54: =數據!D53 -> 無 | AB54: =數據!P53 -> 21.42 | AD54: 巨鉗蟹 | AE54: 地面 | AF54: N | AG54: =AJ54 -> 198 | AH54: D | AI54: =AG54*IF(AH54="G", 450, IF(AH54="D", 350, 0)) * IF(AF54="Y", 1.2, 1)*(INDEX(屬性克制表!$B$2:$T$20, MATCH(AE54, 屬性克制表!$A$2:$A$20, 0), MATCH($L$1, 屬性克制表!$B$1:$T$1, 0)) * INDEX(屬性克制表!$B$2:$T$20, MATCH(AE54, 屬性克制表!$A$2:$A$20, 0), MATCH($M$1, 屬性克制表!$B$1:$T$1, 0))) -> 43312.5 | AJ54: =_xlfn.XLOOKUP(AD54, 數據!B$2:B$50, 數據!M$2:M$50) -> 198 | AK54: =Y54 -> 火伊布 | AL54: =AB54/(INDEX(屬性克制表!$B$2:$T$20, MATCH($A$1, 屬性克制表!$A$2:$A$20, 0), MATCH(Z54, 屬性克制表!$B$1:$T$1, 0)) * INDEX(屬性克制表!$B$2:$T$20, MATCH($A$1, 屬性克制表!$A$2:$A$20, 0), MATCH(AA54, 屬性克制表!$B$1:$T$1, 0))) -> 21.42 | AM54: =Y54 -> 火伊布 | AN54: =AB54/(INDEX(屬性克制表!$B$2:$T$20, MATCH($C$1, 屬性克制表!$A$2:$A$20, 0), MATCH(Z54, 屬性克制表!$B$1:$T$1, 0)) * INDEX(屬性克制表!$B$2:$T$20, MATCH($C$1, 屬性克制表!$A$2:$A$20, 0), MATCH(AA54, 屬性克制表!$B$1:$T$1, 0))) -> 13.3875 | AO54: =Y54 -> 火伊布 | AP54: =AB54/(INDEX(屬性克制表!$B$2:$T$20, MATCH($E$1, 屬性克制表!$A$2:$A$20, 0), MATCH(Z54, 屬性克制表!$B$1:$T$1, 0)) * INDEX(屬性克制表!$B$2:$T$20, MATCH($E$1, 屬性克制表!$A$2:$A$20, 0), MATCH(AA54, 屬性克制表!$B$1:$T$1, 0))) -> 13.3875 | AQ54: =Y54 -> 火伊布 | AR54: =AB54/(INDEX(屬性克制表!$B$2:$T$20, MATCH($G$1, 屬性克制表!$A$2:$A$20, 0), MATCH(Z54, 屬性克制表!$B$1:$T$1, 0)) * INDEX(屬性克制表!$B$2:$T$20, MATCH($G$1, 屬性克制表!$A$2:$A$20, 0), MATCH(AA54, 屬性克制表!$B$1:$T$1, 0))) -> 34.272
...

Sheet 數據
